Workbook

Sheet Sheet1
A1: Provinsi+M22NA1:N506 | B1: Kab/Kota | C1: Persentase Penduduk Miskin (P0) Menurut Kabupaten/Kota (Persen) | D1: Rata-rata Lama Sekolah Penduduk 15+ (Tahun) | E1: Pengeluaran per Kapita Disesuaikan (Ribu Rupiah/Orang/Tahun) | F1: Indeks Pembangunan Manusia | G1: Umur Harapan Hidup (Tahun) | H1: Persentase rumah tangga yang memiliki akses terhadap sanitasi layak | I1: Persentase rumah tangga yang memiliki akses terhadap air minum layak | J1: Tingkat Pengangguran Terbuka | K1: Tingkat Partisipasi Angkatan Kerja | L1: PDRB atas Dasar Harga Konstan menurut Pengeluaran (Rupiah) | M1: Klasifikasi Kemiskinan | O1: Persentase Penduduk Miskin (P0) Menurut Kabupaten/Kota (Persen) | P1: Rata-rata Lama Sekolah Penduduk 15+ (Tahun) | Q1: Pengeluaran per Kapita Disesuaikan (Ribu Rupiah/Orang/Tahun) | R1: Indeks Pembangunan Manusia | S1: Umur Harapan Hidup (Tahun) | T1: Persentase rumah tangga yang memiliki akses terhadap sanitasi layak | U1: Persentase rumah tangga yang memiliki akses terhadap air minum layak | V1: Tingkat Pengangguran Terbuka | W1: Tingkat Partisipasi Angkatan Kerja | X1: PDRB atas Dasar Harga Konstan menurut Pengeluaran (Rupiah)
A2: ACEH | B2: Simeulue | C2: 18.98 | D2: 9.48 | E2: 7148 | F2: 66.41 | G2: 65.28 | H2: 71.56 | I2: 87.45 | J2: 5.71 | K2: 71.15 | L2: 1648096 | M2: 0 | O2: =(C2 - C$516) / C$517 -> 0.90007363 | P2: =(D2 - D$516) / D$517 -> 0.64040648 | Q2: =(E2 - E$516) / E$517 -> -1.1703033 | R2: =(F2 - F$516) / F$517 -> -0.54181599 | S2: =(G2 - G$516) / G$517 -> -1.2708104 | T2: =(H2 - H$516) / H$517 -> -0.30391031 | U2: =(I2 - I$516) / I$517 -> 0.14747735 | V2: =(J2 - J$516) / J$517 -> 0.24692719 | ... X2: =(L2 - L$516) / L$517 -> -0.4245028
A3: ACEH | B3: Aceh Singkil | C3: 20.36 | D3: 8.68 | E3: 8776 | F3: 69.22 | G3: 67.43 | H3: 69.56 | I3: 78.58 | J3: 8.36 | K3: 62.85 | L3: 1780419 | M3: 1 | O3: =(C3 - C$516) / C$517 -> 1.0852726 | P3: =(D3 - D$516) / D$517 -> 0.14938439 | Q3: =(E3 - E$516) / E$517 -> -0.57056109 | R3: =(F3 - F$516) / F$517 -> -0.10888954 | S3: =(G3 - G$516) / G$517 -> -0.64655602 | T3: =(H3 - H$516) / H$517 -> -0.41163719 | U3: =(I3 - I$516) / I$517 -> -0.41798147 | V3: =(J3 - J$516) / J$517 -> 1.2528475 | ... X3: =(L3 - L$516) / L$517 -> -0.42173791
A4: ACEH | B4: Aceh Selatan | C4: 13.18 | D4: 8.88 | E4: 8180 | F4: 67.44 | G4: 64.4 | H4: 62.55 | I4: 79.65 | J4: 6.46 | K4: 60.85 | L4: 4345784 | M4: 0 | O4: =(C4 - C$516) / C$517 -> 0.12170101 | P4: =(D4 - D$516) / D$517 -> 0.27213991 | Q4: =(E4 - E$516) / E$517 -> -0.79012272 | R4: =(F4 - F$516) / F$517 -> -0.38312764 | S4: =(G4 - G$516) / G$517 -> -1.5263192 | T4: =(H4 - H$516) / H$517 -> -0.78921991 | U4: =(I4 - I$516) / I$517 -> -0.34976941 | V4: =(J4 - J$516) / J$517 -> 0.53162163 | ... X4: =(L4 - L$516) / L$517 -> -0.36813456
A5: ACEH | B5: Aceh Tenggara | C5: 13.41 | D5: 9.67 | E5: 8030 | F5: 69.44 | G5: 68.22 | H5: 62.71 | I5: 86.71 | J5: 6.43 | K5: 69.62 | L5: 3487157 | M5: 0 | O5: =(C5 - C$516) / C$517 -> 0.15256751 | P5: =(D5 - D$516) / D$517 -> 0.75702422 | Q5: =(E5 - E$516) / E$517 -> -0.84538152 | R5: =(F5 - F$516) / F$517 -> -0.074994943 | S5: =(G5 - G$516) / G$517 -> -0.41717884 | T5: =(H5 - H$516) / H$517 -> -0.78060176 | U5: =(I5 - I$516) / I$517 -> 0.10030265 | V5: =(J5 - J$516) / J$517 -> 0.52023385 | ... X5: =(L5 - L$516) / L$517 -> -0.38607559
A6: ACEH | B6: Aceh Timur | C6: 14.45 | D6: 8.21 | E6: 8577 | F6: 67.83 | G6: 68.74 | H6: 66.75 | I6: 83.16 | J6: 7.13 | K6: 59.48 | L6: 8433526 | M6: 0 | O6: =(C6 - C$516) / C$517 -> 0.29213777 | P6: =(D6 - D$516) / D$517 -> -0.13909108 | Q6: =(E6 - E$516) / E$517 -> -0.6438711 | R6: =(F6 - F$516) / F$517 -> -0.32304177 | S6: =(G6 - G$516) / G$517 -> -0.26619639 | T6: =(H6 - H$516) / H$517 -> -0.56299346 | U6: =(I6 - I$516) / I$517 -> -0.12600837 | V6: =(J6 - J$516) / J$517 -> 0.78594866 | ... X6: =(L6 - L$516) / L$517 -> -0.28272112
A7: ACEH | B7: Aceh Tengah | C7: 15.26 | D7: 9.86 | E7: 10780 | F7: 73.37 | G7: 68.86 | H7: 90.58 | I7: 90.1 | J7: 2.61 | K7: 76.3 | L7: 5953118 | M7: 0 | O7: =(C7 - C$516) / C$517 -> 0.40084153 | P7: =(D7 - D$516) / D$517 -> 0.87364196 | Q7: =(E7 - E$516) / E$517 -> 0.16769648 | R7: =(F7 - F$516) / F$517 -> 0.53048581 | S7: =(G7 - G$516) / G$517 -> -0.23135428 | T7: =(H7 - H$516) / H$517 -> 0.72057232 | U7: =(I7 - I$516) / I$517 -> 0.31641374 | V7: =(J7 - J$516) / J$517 -> -0.92980981 | ... X7: =(L7 - L$516) / L$517 -> -0.33454929
A8: ACEH | B8: Aceh Barat | C8: 18.81 | D8: 9.55 | E8: 9593 | F8: 71.67 | G8: 67.99 | H8: 89.6 | I8: 94.22 | J8: 7.09 | K8: 60.05 | L8: 7485861 | M8: 0 | O8: =(C8 - C$516) / C$517 -> 0.87725926 | P8: =(D8 - D$516) / D$517 -> 0.68337091 | Q8: =(E8 - E$516) / E$517 -> -0.26958482 | R8: =(F8 - F$516) / F$517 -> 0.26857302 | S8: =(G8 - G$516) / G$517 -> -0.48395954 | T8: =(H8 - H$516) / H$517 -> 0.66778615 | U8: =(I8 - I$516) / I$517 -> 0.57906203 | V8: =(J8 - J$516) / J$517 -> 0.77076495 | ... X8: =(L8 - L$516) / L$517 -> -0.3025226
A9: ACEH | B9: Aceh Besar | C9: 14.05 | D9: 10.33 | E9: 9644 | F9: 73.58 | G9: 69.79 | H9: 87.4 | I9: 82.36 | J9: 7.7 | K9: 61.67 | L9: 10261585 | M9: 0 | O9: =(C9 - C$516) / C$517 -> 0.2384569 | P9: =(D9 - D$516) / D$517 -> 1.1621174 | Q9: =(E9 - E$516) / E$517 -> -0.25079683 | R9: =(F9 - F$516) / F$517 -> 0.56283975 | S9: =(G9 - G$516) / G$517 -> 0.038672024 | T9: =(H9 - H$516) / H$517 -> 0.54928658 | U9: =(I9 - I$516) / I$517 -> -0.17700804 | V9: =(J9 - J$516) / J$517 -> 1.0023164 | ... X9: =(L9 - L$516) / L$517 -> -0.24452379
A10: ACEH | B10: Pidie | C10: 19.59 | D10: 9 | E10: 9860 | F10: 70.7 | G10: 66.95 | H10: 54.1 | I10: 89.24 | J10: 7.28 | K10: 60.29 | L10: 7975099 | M10: 0 | O10: =(C10 - C$516) / C$517 -> 0.98193696 | P10: =(D10 - D$516) / D$517 -> 0.34579323 | Q10: =(E10 - E$516) / E$517 -> -0.17122416 | R10: =(F10 - F$516) / F$517 -> 0.11912866 | S10: =(G10 - G$516) / G$517 -> -0.78592444 | T10: =(H10 - H$516) / H$517 -> -1.244366 | U10: =(I10 - I$516) / I$517 -> 0.2615891 | V10: =(J10 - J$516) / J$517 -> 0.84288754 | ... X10: =(L10 - L$516) / L$517 -> -0.29229996
A11: ACEH | B11: Bireuen | C11: 13.25 | D11: 9.29 | E11: 8867 | F11: 72.33 | G11: 71.26 | H11: 81.89 | I11: 93.53 | J11: 4.32 | K11: 65.91 | L11: 10374480 | M11: 0 | O11: =(C11 - C$516) / C$517 -> 0.13109516 | P11: =(D11 - D$516) / D$517 -> 0.52378873 | Q11: =(E11 - E$516) / E$517 -> -0.53703742 | R11: =(F11 - F$516) / F$517 -> 0.37025681 | S11: =(G11 - G$516) / G$517 -> 0.4654878 | T11: =(H11 - H$516) / H$517 -> 0.25249902 | U11: =(I11 - I$516) / I$517 -> 0.53507482 | V11: =(J11 - J$516) / J$517 -> -0.2807065 | ... X11: =(L11 - L$516) / L$517 -> -0.24216485
A12: ACEH | B12: Aceh Utara | C12: 17.43 | D12: 8.64 | E12: 8201 | F12: 69.46 | G12: 68.81 | H12: 79.97 | I12: 91.09 | J12: 8.31 | K12: 58.47 | L12: 16924103 | M12: 0 | O12: =(C12 - C$516) / C$517 -> 0.69206026 | P12: =(D12 - D$516) / D$517 -> 0.12483329 | Q12: =(E12 - E$516) / E$517 -> -0.78238649 | R12: =(F12 - F$516) / F$517 -> -0.071913616 | S12: =(G12 - G$516) / G$517 -> -0.24587183 | T12: =(H12 - H$516) / H$517 -> 0.14908122 | U12: =(I12 - I$516) / I$517 -> 0.37952583 | V12: =(J12 - J$516) / J$517 -> 1.2338679 | ... X12: =(L12 - L$516) / L$517 -> -0.10531036
A13: ACEH | B13: Aceh Barat Daya | C13: 16.34 | D13: 8.67 | E13: 8428 | F13: 66.99 | G13: 65.06 | H13: 65.71 | I13: 95.34 | J13: 4.04 | K13: 57.91 | L13: 3069805 | M13: 0 | O13: =(C13 - C$516) / C$517 -> 0.54577988 | P13: =(D13 - D$516) / D$517 -> 0.14324662 | Q13: =(E13 - E$516) / E$517 -> -0.6987615 | R13: =(F13 - F$516) / F$517 -> -0.4524575 | S13: =(G13 - G$516) / G$517 -> -1.3346876 | T13: =(H13 - H$516) / H$517 -> -0.61901144 | U13: =(I13 - I$516) / I$517 -> 0.65046156 | V13: =(J13 - J$516) / J$517 -> -0.38699242 | ... X13: =(L13 - L$516) / L$517 -> -0.39479617
... A515: PAPUA | B515: Kota Jayapura | C515: 11.39 | D515: 11.57 | E515: 14937 | F515: 80.11 | G515: 70.52 | H515: 85.31 | I515: 97.1 | J515: 11.67 | K515: 63.75 | L515: 22852202 | M515: 0 | O515: =(C515 - C$516) / C$517 -> -0.11852089 | P515: =(D515 - D$516) / D$517 -> 1.9232017 | Q515: =(E515 - E$516) / E$517 -> 1.699102 | R515: =(F515 - F$516) / F$517 -> 1.568893 | S515: =(G515 - G$516) / G$517 -> 0.25062816 | T515: =(H515 - H$516) / H$517 -> 0.43671199 | U515: =(I515 - I$516) / I$517 -> 0.76266083 | V515: =(J515 - J$516) / J$517 -> 2.509299 | ... X515: =(L515 - L$516) / L$517 -> 0.018557378
B516: Mean | C516: =AVERAGE(C2:C515) -> 12.273152 | D516: =AVERAGE(D2:D515) -> 8.4366148 | E516: =AVERAGE(E2:E515) -> 10324.788 | F516: =AVERAGE(F2:F515) -> 69.92677 | G516: =AVERAGE(G2:G515) -> 69.656809 | H516: =AVERAGE(H2:H515) -> 77.202237 | I516: =AVERAGE(I2:I515) -> 85.136615 | J516: =AVERAGE(J2:J515) -> 5.0594942 | ... L516: =AVERAGE(L2:L515) -> 21964077
B517: Standa Deviasi | C517: =_xlfn.STDEV.P(C2:C515) -> 7.451444 | D517: =_xlfn.STDEV.P(D2:D515) -> 1.6292546 | E517: =_xlfn.STDEV.P(E2:E515) -> 2714.4998 | F517: =_xlfn.STDEV.P(F2:F515) -> 6.49071 | G517: =_xlfn.STDEV.P(G2:G515) -> 3.4441089 | H517: =_xlfn.STDEV.P(H2:H515) -> 18.565468 | I517: =_xlfn.STDEV.P(I2:I515) -> 15.686377 | J517: =_xlfn.STDEV.P(J2:J515) -> 2.6344034 | ... L517: =_xlfn.STDEV.P(L2:L515) -> 47858298

Sheet Sheet2
A1: Provinsi+M22NA1:N506 | B1: Kab/Kota | C1: Persentase Penduduk Miskin (P0) Menurut Kabupaten/Kota (Persen) | D1: Rata-rata Lama Sekolah Penduduk 15+ (Tahun) | E1: Pengeluaran per Kapita Disesuaikan (Ribu Rupiah/Orang/Tahun) | F1: Indeks Pembangunan Manusia | G1: Umur Harapan Hidup (Tahun) | H1: Persentase rumah tangga yang memiliki akses terhadap sanitasi layak | I1: Persentase rumah tangga yang memiliki akses terhadap air minum layak | J1: Tingkat Pengangguran Terbuka | K1: Tingkat Partisipasi Angkatan Kerja | L1: PDRB atas Dasar Harga Konstan menurut Pengeluaran (Rupiah) | N1: JARAK KE C1 | O1: JARAK KE C2 | P1: PREDIKSI | Q1: AKURASI
A2: ACEH | B2: Simeulue | C2: 0.90007363 | D2: 0.64040648 | E2: -1.1703033 | F2: -0.54181599 | G2: -1.2708104 | H2: -0.30391031 | I2: 0.14747735 | J2: 0.24692719 | K2: 0.26377109 | L2: -0.4245028 | N2: =SQRT((C2-$C$520)^2+(D2-$D$520)^2+(E2-$E$520)^2+(F2-$F$520)^2+(G2-$G$520)^2+(H2-$H$520)^2+(I2-$I$520)^2+(J2-$J$520)^2+(K2-$K$520)^2+(L2-$L$520)^2) -> 0 | O2: =SQRT((C2-$C$521)^2+(D2-$D$521)^2+(E2-$E$521)^2+(F2-$F$521)^2+(G2-$G$521)^2+(H2-$H$521)^2+(I2-$I$521)^2+(J2-$J$521)^2+(K2-$K$521)^2+(L2-$L$521)^2) -> 6.1384341 | P2: =IF(N2<=O2, 0, 1) -> 0 | Q2: =IF(P2=Sheet1!M2, 1, 0) -> 1
A3: ACEH | B3: Aceh Singkil | C3: 1.0852726 | D3: 0.14938439 | E3: -0.57056109 | F3: -0.10888954 | G3: -0.64655602 | H3: -0.41163719 | I3: -0.41798147 | J3: 1.2528475 | K3: -1.0350969 | L3: -0.42173791 | N3: =SQRT((C3-$C$520)^2+(D3-$D$520)^2+(E3-$E$520)^2+(F3-$F$520)^2+(G3-$G$520)^2+(H3-$H$520)^2+(I3-$I$520)^2+(J3-$J$520)^2+(K3-$K$520)^2+(L3-$L$520)^2) -> 2.0597332 | O3: =SQRT((C3-$C$521)^2+(D3-$D$521)^2+(E3-$E$521)^2+(F3-$F$521)^2+(G3-$G$521)^2+(H3-$H$521)^2+(I3-$I$521)^2+(J3-$J$521)^2+(K3-$K$521)^2+(L3-$L$521)^2) -> 5.5472547 | P3: =IF(N3<=O3, 0, 1) -> 0 | Q3: =IF(P3=Sheet1!M3, 1, 0) -> 0
A4: ACEH | B4: Aceh Selatan | C4: 0.12170101 | D4: 0.27213991 | E4: -0.79012272 | F4: -0.38312764 | G4: -1.5263192 | H4: -0.78921991 | I4: -0.34976941 | J4: 0.53162163 | K4: -1.3480771 | L4: -0.36813456 | N4: =SQRT((C4-$C$520)^2+(D4-$D$520)^2+(E4-$E$520)^2+(F4-$F$520)^2+(G4-$G$520)^2+(H4-$H$520)^2+(I4-$I$520)^2+(J4-$J$520)^2+(K4-$K$520)^2+(L4-$L$520)^2) -> 2.03508 | O4: =SQRT((C4-$C$521)^2+(D4-$D$521)^2+(E4-$E$521)^2+(F4-$F$521)^2+(G4-$G$521)^2+(H4-$H$521)^2+(I4-$I$521)^2+(J4-$J$521)^2+(K4-$K$521)^2+(L4-$L$521)^2) -> 5.9672563 | P4: =IF(N4<=O4, 0, 1) -> 0 | Q4: =IF(P4=Sheet1!M4, 1, 0) -> 1
A5: ACEH | B5: Aceh Tenggara | C5: 0.15256751 | D5: 0.75702422 | E5: -0.84538152 | F5: -0.074994943 | G5: -0.41717884 | H5: -0.78060176 | I5: 0.10030265 | J5: 0.52023385 | K5: 0.024341215 | L5: -0.38607559 | N5: =SQRT((C5-$C$520)^2+(D5-$D$520)^2+(E5-$E$520)^2+(F5-$F$520)^2+(G5-$G$520)^2+(H5-$H$520)^2+(I5-$I$520)^2+(J5-$J$520)^2+(K5-$K$520)^2+(L5-$L$520)^2) -> 1.40979 | O5: =SQRT((C5-$C$521)^2+(D5-$D$521)^2+(E5-$E$521)^2+(F5-$F$521)^2+(G5-$G$521)^2+(H5-$H$521)^2+(I5-$I$521)^2+(J5-$J$521)^2+(K5-$K$521)^2+(L5-$L$521)^2) -> 5.3784932 | P5: =IF(N5<=O5, 0, 1) -> 0 | Q5: =IF(P5=Sheet1!M5, 1, 0) -> 1
A6: ACEH | B6: Aceh Timur | C6: 0.29213777 | D6: -0.13909108 | E6: -0.6438711 | F6: -0.32304177 | G6: -0.26619639 | H6: -0.56299346 | I6: -0.12600837 | J6: 0.78594866 | K6: -1.5624686 | L6: -0.28272112 | N6: =SQRT((C6-$C$520)^2+(D6-$D$520)^2+(E6-$E$520)^2+(F6-$F$520)^2+(G6-$G$520)^2+(H6-$H$520)^2+(I6-$I$520)^2+(J6-$J$520)^2+(K6-$K$520)^2+(L6-$L$520)^2) -> 2.4696479 | O6: =SQRT((C6-$C$521)^2+(D6-$D$521)^2+(E6-$E$521)^2+(F6-$F$521)^2+(G6-$G$521)^2+(H6-$H$521)^2+(I6-$I$521)^2+(J6-$J$521)^2+(K6-$K$521)^2+(L6-$L$521)^2) -> 5.6172594 | P6: =IF(N6<=O6, 0, 1) -> 0 | Q6: =IF(P6=Sheet1!M6, 1, 0) -> 1
A7: ACEH | B7: Aceh Tengah | C7: 0.40084153 | D7: 0.87364196 | E7: 0.16769648 | F7: 0.53048581 | G7: -0.23135428 | H7: 0.72057232 | I7: 0.31641374 | J7: -0.92980981 | K7: 1.0696952 | L7: -0.33454929 | N7: =SQRT((C7-$C$520)^2+(D7-$D$520)^2+(E7-$E$520)^2+(F7-$F$520)^2+(G7-$G$520)^2+(H7-$H$520)^2+(I7-$I$520)^2+(J7-$J$520)^2+(K7-$K$520)^2+(L7-$L$520)^2) -> 2.7284784 | O7: =SQRT((C7-$C$521)^2+(D7-$D$521)^2+(E7-$E$521)^2+(F7-$F$521)^2+(G7-$G$521)^2+(H7-$H$521)^2+(I7-$I$521)^2+(J7-$J$521)^2+(K7-$K$521)^2+(L7-$L$521)^2) -> 4.9397498 | P7: =IF(N7<=O7, 0, 1) -> 0 | Q7: =IF(P7=Sheet1!M7, 1, 0) -> 1
A8: ACEH | B8: Aceh Barat | C8: 0.87725926 | D8: 0.68337091 | E8: -0.26958482 | F8: 0.26857302 | G8: -0.48395954 | H8: 0.66778615 | I8: 0.57906203 | J8: 0.77076495 | K8: -1.4732692 | L8: -0.3025226 | N8: =SQRT((C8-$C$520)^2+(D8-$D$520)^2+(E8-$E$520)^2+(F8-$F$520)^2+(G8-$G$520)^2+(H8-$H$520)^2+(I8-$I$520)^2+(J8-$J$520)^2+(K8-$K$520)^2+(L8-$L$520)^2) -> 2.5547169 | O8: =SQRT((C8-$C$521)^2+(D8-$D$521)^2+(E8-$E$521)^2+(F8-$F$521)^2+(G8-$G$521)^2+(H8-$H$521)^2+(I8-$I$521)^2+(J8-$J$521)^2+(K8-$K$521)^2+(L8-$L$521)^2) -> 4.5186444 | P8: =IF(N8<=O8, 0, 1) -> 0 | Q8: =IF(P8=Sheet1!M8, 1, 0) -> 1
A9: ACEH | B9: Aceh Besar | C9: 0.2384569 | D9: 1.1621174 | E9: -0.25079683 | F9: 0.56283975 | G9: 0.038672024 | H9: 0.54928658 | I9: -0.17700804 | J9: 1.0023164 | K9: -1.2197552 | L9: -0.24452379 | N9: =SQRT((C9-$C$520)^2+(D9-$D$520)^2+(E9-$E$520)^2+(F9-$F$520)^2+(G9-$G$520)^2+(H9-$H$520)^2+(I9-$I$520)^2+(J9-$J$520)^2+(K9-$K$520)^2+(L9-$L$520)^2) -> 2.850879 | O9: =SQRT((C9-$C$521)^2+(D9-$D$521)^2+(E9-$E$521)^2+(F9-$F$521)^2+(G9-$G$521)^2+(H9-$H$521)^2+(I9-$I$521)^2+(J9-$J$521)^2+(K9-$K$521)^2+(L9-$L$521)^2) -> 3.9847435 | P9: =IF(N9<=O9, 0, 1) -> 0 | Q9: =IF(P9=Sheet1!M9, 1, 0) -> 1
A10: ACEH | B10: Pidie | C10: 0.98193696 | D10: 0.34579323 | E10: -0.17122416 | F10: 0.11912866 | G10: -0.78592444 | H10: -1.244366 | I10: 0.2615891 | J10: 0.84288754 | K10: -1.4357116 | L10: -0.29229996 | N10: =SQRT((C10-$C$520)^2+(D10-$D$520)^2+(E10-$E$520)^2+(F10-$F$520)^2+(G10-$G$520)^2+(H10-$H$520)^2+(I10-$I$520)^2+(J10-$J$520)^2+(K10-$K$520)^2+(L10-$L$520)^2) -> 2.4335131 | O10: =SQRT((C10-$C$521)^2+(D10-$D$521)^2+(E10-$E$521)^2+(F10-$F$521)^2+(G10-$G$521)^2+(H10-$H$521)^2+(I10-$I$521)^2+(J10-$J$521)^2+(K10-$K$521)^2+(L10-$L$521)^2) -> 5.3876956 | P10: =IF(N10<=O10, 0, 1) -> 0 | Q10: =IF(P10=Sheet1!M10, 1, 0) -> 1
A11: ACEH | B11: Bireuen | C11: 0.13109516 | D11: 0.52378873 | E11: -0.53703742 | F11: 0.37025681 | G11: 0.4654878 | H11: 0.25249902 | I11: 0.53507482 | J11: -0.2807065 | K11: -0.55623711 | L11: -0.24216485 | N11: =SQRT((C11-$C$520)^2+(D11-$D$520)^2+(E11-$E$520)^2+(F11-$F$520)^2+(G11-$G$520)^2+(H11-$H$520)^2+(I11-$I$520)^2+(J11-$J$520)^2+(K11-$K$520)^2+(L11-$L$520)^2) -> 2.5092713 | O11: =SQRT((C11-$C$521)^2+(D11-$D$521)^2+(E11-$E$521)^2+(F11-$F$521)^2+(G11-$G$521)^2+(H11-$H$521)^2+(I11-$I$521)^2+(J11-$J$521)^2+(K11-$K$521)^2+(L11-$L$521)^2) -> 4.7600929 | P11: =IF(N11<=O11, 0, 1) -> 0 | Q11: =IF(P11=Sheet1!M11, 1, 0) -> 1
A12: ACEH | B12: Aceh Utara | C12: 0.69206026 | D12: 0.12483329 | E12: -0.78238649 | F12: -0.071913616 | G12: -0.24587183 | H12: 0.14908122 | I12: 0.37952583 | J12: 1.2338679 | K12: -1.7205236 | L12: -0.10531036 | N12: =SQRT((C12-$C$520)^2+(D12-$D$520)^2+(E12-$E$520)^2+(F12-$F$520)^2+(G12-$G$520)^2+(H12-$H$520)^2+(I12-$I$520)^2+(J12-$J$520)^2+(K12-$K$520)^2+(L12-$L$520)^2) -> 2.6463713 | O12: =SQRT((C12-$C$521)^2+(D12-$D$521)^2+(E12-$E$521)^2+(F12-$F$521)^2+(G12-$G$521)^2+(H12-$H$521)^2+(I12-$I$521)^2+(J12-$J$521)^2+(K12-$K$521)^2+(L12-$L$521)^2) -> 5.2417044 | P12: =IF(N12<=O12, 0, 1) -> 0 | Q12: =IF(P12=Sheet1!M12, 1, 0) -> 1
A13: ACEH | B13: Aceh Barat Daya | C13: 0.54577988 | D13: 0.14324662 | E13: -0.6987615 | F13: -0.4524575 | G13: -1.3346876 | H13: -0.61901144 | I13: 0.65046156 | J13: -0.38699242 | K13: -1.808158 | L13: -0.39479617 | N13: =SQRT((C13-$C$520)^2+(D13-$D$520)^2+(E13-$E$520)^2+(F13-$F$520)^2+(G13-$G$520)^2+(H13-$H$520)^2+(I13-$I$520)^2+(J13-$J$520)^2+(K13-$K$520)^2+(L13-$L$520)^2) -> 2.3780281 | O13: =SQRT((C13-$C$521)^2+(D13-$D$521)^2+(E13-$E$521)^2+(F13-$F$521)^2+(G13-$G$521)^2+(H13-$H$521)^2+(I13-$I$521)^2+(J13-$J$521)^2+(K13-$K$521)^2+(L13-$L$521)^2) -> 6.087932 | P13: =IF(N13<=O13, 0, 1) -> 0 | Q13: =IF(P13=Sheet1!M13, 1, 0) -> 1
... A515: PAPUA | B515: Kota Jayapura | C515: -0.11852089 | D515: 1.9232017 | E515: 1.699102 | F515: 1.568893 | G515: 0.25062816 | H515: 0.43671199 | I515: 0.76266083 | J515: 2.509299 | K515: -0.89425576 | L515: 0.018557378 | N515: =SQRT((C515-$C$520)^2+(D515-$D$520)^2+(E515-$E$520)^2+(F515-$F$520)^2+(G515-$G$520)^2+(H515-$H$520)^2+(I515-$I$520)^2+(J515-$J$520)^2+(K515-$K$520)^2+(L515-$L$520)^2) -> 5.0268359 | O515: =SQRT((C515-$C$521)^2+(D515-$D$521)^2+(E515-$E$521)^2+(F515-$F$521)^2+(G515-$G$521)^2+(H515-$H$521)^2+(I515-$I$521)^2+(J515-$J$521)^2+(K515-$K$521)^2+(L515-$L$521)^2) -> 1.9876284 | P515: =IF(N515<=O515, 0, 1) -> 1 | Q515: =IF(P515=Sheet1!M515, 1, 0) -> 0
P516: total akurasi | Q516: =(SUM(Q2:Q515)/514)*100 -> 69.455253
A519: LAMA
A520: ACEH | B520: Simeulue | C520: 0.90007363 | D520: 0.64040648 | E520: -1.1703033 | F520: -0.54181599 | G520: -1.2708104 | H520: -0.30391031 | I520: 0.14747735 | J520: 0.24692719 | K520: 0.26377109 | L520: -0.4245028
A521: ACEH | B521: Kota Banda Aceh | C521: -0.62580511 | D521: 2.6965614 | E521: 2.41894 | F521: 2.4316646 | G521: 0.54097903 | H521: 1.2215023 | I521: 0.90737239 | J521: 1.4730112 | K521: -1.0116234 | L521: -0.13602044
A524: BARU
A525: ACEH | B525: Simeulue | C525: =AVERAGEIF($P$2:$P$515, 0, C$2:C$515) -> 0.17054548 | D525: =AVERAGEIF($P$2:$P$515, 0, D$2:D$515) -> -0.30904449 | E525: =AVERAGEIF($P$2:$P$515, 0, E$2:E$515) -> -0.32220509 | F525: =AVERAGEIF($P$2:$P$515, 0, F$2:F$515) -> -0.31828005 | G525: =AVERAGEIF($P$2:$P$515, 0, G$2:G$515) -> -0.21781382 | H525: =AVERAGEIF($P$2:$P$515, 0, H$2:H$515) -> -0.18155418 | I525: =AVERAGEIF($P$2:$P$515, 0, I$2:I$515) -> -0.17504686 | J525: =AVERAGEIF($P$2:$P$515, 0, J$2:J$515) -> -0.26586706 | ... L525: =AVERAGEIF($P$2:$P$515, 0, L$2:L$515) -> -0.17179168
A526: ACEH | B526: Kota Banda Aceh | C526: =AVERAGEIF($P$2:$P$515, 1, C$2:C$515) -> -0.75219531 | D526: =AVERAGEIF($P$2:$P$515, 1, D$2:D$515) -> 1.3630488 | E526: =AVERAGEIF($P$2:$P$515, 1, E$2:E$515) -> 1.421094 | F526: =AVERAGEIF($P$2:$P$515, 1, F$2:F$515) -> 1.4037825 | G526: =AVERAGEIF($P$2:$P$515, 1, G$2:G$515) -> 0.96067356 | H526: =AVERAGEIF($P$2:$P$515, 1, H$2:H$515) -> 0.80074947 | I526: =AVERAGEIF($P$2:$P$515, 1, I$2:I$515) -> 0.7720488 | J526: =AVERAGEIF($P$2:$P$515, 1, J$2:J$515) -> 1.1726136 | ... L526: =AVERAGEIF($P$2:$P$515, 1, L$2:L$515) -> 0.75769173

Sheet Sheet3
A1: Provinsi+M22NA1:N506 | B1: Kab/Kota | C1: Persentase Penduduk Miskin (P0) Menurut Kabupaten/Kota (Persen) | D1: Rata-rata Lama Sekolah Penduduk 15+ (Tahun) | E1: Pengeluaran per Kapita Disesuaikan (Ribu Rupiah/Orang/Tahun) | F1: Indeks Pembangunan Manusia | G1: Umur Harapan Hidup (Tahun) | H1: Persentase rumah tangga yang memiliki akses terhadap sanitasi layak | I1: Persentase rumah tangga yang memiliki akses terhadap air minum layak | J1: Tingkat Pengangguran Terbuka | K1: Tingkat Partisipasi Angkatan Kerja | L1: PDRB atas Dasar Harga Konstan menurut Pengeluaran (Rupiah) | N1: JARAK KE C1 | O1: JARAK KE C2 | P1: PREDIKSI | Q1: AKURASI
A2: ACEH | B2: Simeulue | C2: 0.90007363 | D2: 0.64040648 | E2: -1.1703033 | F2: -0.54181599 | G2: -1.2708104 | H2: -0.30391031 | I2: 0.14747735 | J2: 0.24692719 | K2: 0.26377109 | L2: -0.4245028 | N2: =SQRT((C2-Sheet2!$C$525)^2+(D2-Sheet2!$D$525)^2+(E2-Sheet2!$E$525)^2+(F2-Sheet2!$F$525)^2+(G2-Sheet2!$G$525)^2+(H2-Sheet2!$H$525)^2+(I2-Sheet2!$I$525)^2+(J2-Sheet2!$J$525)^2+(K2-Sheet2!$K$525)^2+(L2-Sheet2!$L$525)^2) -> 1.9424504 | O2: =SQRT((C2-Sheet2!$C$526)^2+(D2-Sheet2!$D$526)^2+(E2-Sheet2!$E$526)^2+(F2-Sheet2!$F$526)^2+(G2-Sheet2!$G$526)^2+(H2-Sheet2!$H$526)^2+(I2-Sheet2!$I$526)^2+(J2-Sheet2!$J$526)^2+(K2-Sheet2!$K$526)^2+(L2-Sheet2!$L$526)^2) -> 4.8337755 | P2: =IF(N2<=O2, 0, 1) -> 0 | Q2: =IF(P2=Sheet1!$M2, 1, 0) -> 1
A3: ACEH | B3: Aceh Singkil | C3: 1.0852726 | D3: 0.14938439 | E3: -0.57056109 | F3: -0.10888954 | G3: -0.64655602 | H3: -0.41163719 | I3: -0.41798147 | J3: 1.2528475 | K3: -1.0350969 | L3: -0.42173791 | N3: =SQRT((C3-Sheet2!$C$525)^2+(D3-Sheet2!$D$525)^2+(E3-Sheet2!$E$525)^2+(F3-Sheet2!$F$525)^2+(G3-Sheet2!$G$525)^2+(H3-Sheet2!$H$525)^2+(I3-Sheet2!$I$525)^2+(J3-Sheet2!$J$525)^2+(K3-Sheet2!$K$525)^2+(L3-Sheet2!$L$525)^2) -> 2.2793501 | O3: =SQRT((C3-Sheet2!$C$526)^2+(D3-Sheet2!$D$526)^2+(E3-Sheet2!$E$526)^2+(F3-Sheet2!$F$526)^2+(G3-Sheet2!$G$526)^2+(H3-Sheet2!$H$526)^2+(I3-Sheet2!$I$526)^2+(J3-Sheet2!$J$526)^2+(K3-Sheet2!$K$526)^2+(L3-Sheet2!$L$526)^2) -> 4.2602025 | P3: =IF(N3<=O3, 0, 1) -> 0 | Q3: =IF(P3=Sheet1!$M3, 1, 0) -> 0
A4: ACEH | B4: Aceh Selatan | C4: 0.12170101 | D4: 0.27213991 | E4: -0.79012272 | F4: -0.38312764 | G4: -1.5263192 | H4: -0.78921991 | I4: -0.34976941 | J4: 0.53162163 | K4: -1.3480771 | L4: -0.36813456 | N4: =SQRT((C4-Sheet2!$C$525)^2+(D4-Sheet2!$D$525)^2+(E4-Sheet2!$E$525)^2+(F4-Sheet2!$F$525)^2+(G4-Sheet2!$G$525)^2+(H4-Sheet2!$H$525)^2+(I4-Sheet2!$I$525)^2+(J4-Sheet2!$J$525)^2+(K4-Sheet2!$K$525)^2+(L4-Sheet2!$L$525)^2) -> 2.3581661 | O4: =SQRT((C4-Sheet2!$C$526)^2+(D4-Sheet2!$D$526)^2+(E4-Sheet2!$E$526)^2+(F4-Sheet2!$F$526)^2+(G4-Sheet2!$G$526)^2+(H4-Sheet2!$H$526)^2+(I4-Sheet2!$I$526)^2+(J4-Sheet2!$J$526)^2+(K4-Sheet2!$K$526)^2+(L4-Sheet2!$L$526)^2) -> 4.7145642 | P4: =IF(N4<=O4, 0, 1) -> 0 | Q4: =IF(P4=Sheet1!$M4, 1, 0) -> 1
A5: ACEH | B5: Aceh Tenggara | C5: 0.15256751 | D5: 0.75702422 | E5: -0.84538152 | F5: -0.074994943 | G5: -0.41717884 | H5: -0.78060176 | I5: 0.10030265 | J5: 0.52023385 | K5: 0.024341215 | L5: -0.38607559 | N5: =SQRT((C5-Sheet2!$C$525)^2+(D5-Sheet2!$D$525)^2+(E5-Sheet2!$E$525)^2+(F5-Sheet2!$F$525)^2+(G5-Sheet2!$G$525)^2+(H5-Sheet2!$H$525)^2+(I5-Sheet2!$I$525)^2+(J5-Sheet2!$J$525)^2+(K5-Sheet2!$K$525)^2+(L5-Sheet2!$L$525)^2) -> 1.6189955 | O5: =SQRT((C5-Sheet2!$C$526)^2+(D5-Sheet2!$D$526)^2+(E5-Sheet2!$E$526)^2+(F5-Sheet2!$F$526)^2+(G5-Sheet2!$G$526)^2+(H5-Sheet2!$H$526)^2+(I5-Sheet2!$I$526)^2+(J5-Sheet2!$J$526)^2+(K5-Sheet2!$K$526)^2+(L5-Sheet2!$L$526)^2) -> 3.9369425 | P5: =IF(N5<=O5, 0, 1) -> 0 | Q5: =IF(P5=Sheet1!$M5, 1, 0) -> 1
A6: ACEH | B6: Aceh Timur | C6: 0.29213777 | D6: -0.13909108 | E6: -0.6438711 | F6: -0.32304177 | G6: -0.26619639 | H6: -0.56299346 | I6: -0.12600837 | J6: 0.78594866 | K6: -1.5624686 | L6: -0.28272112 | N6: =SQRT((C6-Sheet2!$C$525)^2+(D6-Sheet2!$D$525)^2+(E6-Sheet2!$E$525)^2+(F6-Sheet2!$F$525)^2+(G6-Sheet2!$G$525)^2+(H6-Sheet2!$H$525)^2+(I6-Sheet2!$I$525)^2+(J6-Sheet2!$J$525)^2+(K6-Sheet2!$K$525)^2+(L6-Sheet2!$L$525)^2) -> 2.0762237 | O6: =SQRT((C6-Sheet2!$C$526)^2+(D6-Sheet2!$D$526)^2+(E6-Sheet2!$E$526)^2+(F6-Sheet2!$F$526)^2+(G6-Sheet2!$G$526)^2+(H6-Sheet2!$H$526)^2+(I6-Sheet2!$I$526)^2+(J6-Sheet2!$J$526)^2+(K6-Sheet2!$K$526)^2+(L6-Sheet2!$L$526)^2) -> 4.1108008 | P6: =IF(N6<=O6, 0, 1) -> 0 | Q6: =IF(P6=Sheet1!$M6, 1, 0) -> 1
A7: ACEH | B7: Aceh Tengah | C7: 0.40084153 | D7: 0.87364196 | E7: 0.16769648 | F7: 0.53048581 | G7: -0.23135428 | H7: 0.72057232 | I7: 0.31641374 | J7: -0.92980981 | K7: 1.0696952 | L7: -0.33454929 | N7: =SQRT((C7-Sheet2!$C$525)^2+(D7-Sheet2!$D$525)^2+(E7-Sheet2!$E$525)^2+(F7-Sheet2!$F$525)^2+(G7-Sheet2!$G$525)^2+(H7-Sheet2!$H$525)^2+(I7-Sheet2!$I$525)^2+(J7-Sheet2!$J$525)^2+(K7-Sheet2!$K$525)^2+(L7-Sheet2!$L$525)^2) -> 2.1912132 | O7: =SQRT((C7-Sheet2!$C$526)^2+(D7-Sheet2!$D$526)^2+(E7-Sheet2!$E$526)^2+(F7-Sheet2!$F$526)^2+(G7-Sheet2!$G$526)^2+(H7-Sheet2!$H$526)^2+(I7-Sheet2!$I$526)^2+(J7-Sheet2!$J$526)^2+(K7-Sheet2!$K$526)^2+(L7-Sheet2!$L$526)^2) -> 3.739132 | P7: =IF(N7<=O7, 0, 1) -> 0 | Q7: =IF(P7=Sheet1!$M7, 1, 0) -> 1
A8: ACEH | B8: Aceh Barat | C8: 0.87725926 | D8: 0.68337091 | E8: -0.26958482 | F8: 0.26857302 | G8: -0.48395954 | H8: 0.66778615 | I8: 0.57906203 | J8: 0.77076495 | K8: -1.4732692 | L8: -0.3025226 | N8: =SQRT((C8-Sheet2!$C$525)^2+(D8-Sheet2!$D$525)^2+(E8-Sheet2!$E$525)^2+(F8-Sheet2!$F$525)^2+(G8-Sheet2!$G$525)^2+(H8-Sheet2!$H$525)^2+(I8-Sheet2!$I$525)^2+(J8-Sheet2!$J$525)^2+(K8-Sheet2!$K$525)^2+(L8-Sheet2!$L$525)^2) -> 2.6235856 | O8: =SQRT((C8-Sheet2!$C$526)^2+(D8-Sheet2!$D$526)^2+(E8-Sheet2!$E$526)^2+(F8-Sheet2!$F$526)^2+(G8-Sheet2!$G$526)^2+(H8-Sheet2!$H$526)^2+(I8-Sheet2!$I$526)^2+(J8-Sheet2!$J$526)^2+(K8-Sheet2!$K$526)^2+(L8-Sheet2!$L$526)^2) -> 3.3811625 | P8: =IF(N8<=O8, 0, 1) -> 0 | Q8: =IF(P8=Sheet1!$M8, 1, 0) -> 1
A9: ACEH | B9: Aceh Besar | C9: 0.2384569 | D9: 1.1621174 | E9: -0.25079683 | F9: 0.56283975 | G9: 0.038672024 | H9: 0.54928658 | I9: -0.17700804 | J9: 1.0023164 | K9: -1.2197552 | L9: -0.24452379 | N9: =SQRT((C9-Sheet2!$C$525)^2+(D9-Sheet2!$D$525)^2+(E9-Sheet2!$E$525)^2+(F9-Sheet2!$F$525)^2+(G9-Sheet2!$G$525)^2+(H9-Sheet2!$H$525)^2+(I9-Sheet2!$I$525)^2+(J9-Sheet2!$J$525)^2+(K9-Sheet2!$K$525)^2+(L9-Sheet2!$L$525)^2) -> 2.6476144 | O9: =SQRT((C9-Sheet2!$C$526)^2+(D9-Sheet2!$D$526)^2+(E9-Sheet2!$E$526)^2+(F9-Sheet2!$F$526)^2+(G9-Sheet2!$G$526)^2+(H9-Sheet2!$H$526)^2+(I9-Sheet2!$I$526)^2+(J9-Sheet2!$J$526)^2+(K9-Sheet2!$K$526)^2+(L9-Sheet2!$L$526)^2) -> 2.7821224 | P9: =IF(N9<=O9, 0, 1) -> 0 | Q9: =IF(P9=Sheet1!$M9, 1, 0) -> 1
A10: ACEH | B10: Pidie | C10: 0.98193696 | D10: 0.34579323 | E10: -0.17122416 | F10: 0.11912866 | G10: -0.78592444 | H10: -1.244366 | I10: 0.2615891 | J10: 0.84288754 | K10: -1.4357116 | L10: -0.29229996 | N10: =SQRT((C10-Sheet2!$C$525)^2+(D10-Sheet2!$D$525)^2+(E10-Sheet2!$E$525)^2+(F10-Sheet2!$F$525)^2+(G10-Sheet2!$G$525)^2+(H10-Sheet2!$H$525)^2+(I10-Sheet2!$I$525)^2+(J10-Sheet2!$J$525)^2+(K10-Sheet2!$K$525)^2+(L10-Sheet2!$L$525)^2) -> 2.5821589 | O10: =SQRT((C10-Sheet2!$C$526)^2+(D10-Sheet2!$D$526)^2+(E10-Sheet2!$E$526)^2+(F10-Sheet2!$F$526)^2+(G10-Sheet2!$G$526)^2+(H10-Sheet2!$H$526)^2+(I10-Sheet2!$I$526)^2+(J10-Sheet2!$J$526)^2+(K10-Sheet2!$K$526)^2+(L10-Sheet2!$L$526)^2) -> 4.1964425 | P10: =IF(N10<=O10, 0, 1) -> 0 | Q10: =IF(P10=Sheet1!$M10, 1, 0) -> 1
A11: ACEH | B11: Bireuen | C11: 0.13109516 | D11: 0.52378873 | E11: -0.53703742 | F11: 0.37025681 | G11: 0.4654878 | H11: 0.25249902 | I11: 0.53507482 | J11: -0.2807065 | K11: -0.55623711 | L11: -0.24216485 | N11: =SQRT((C11-Sheet2!$C$525)^2+(D11-Sheet2!$D$525)^2+(E11-Sheet2!$E$525)^2+(F11-Sheet2!$F$525)^2+(G11-Sheet2!$G$525)^2+(H11-Sheet2!$H$525)^2+(I11-Sheet2!$I$525)^2+(J11-Sheet2!$J$525)^2+(K11-Sheet2!$K$525)^2+(L11-Sheet2!$L$525)^2) -> 1.692152 | O11: =SQRT((C11-Sheet2!$C$526)^2+(D11-Sheet2!$D$526)^2+(E11-Sheet2!$E$526)^2+(F11-Sheet2!$F$526)^2+(G11-Sheet2!$G$526)^2+(H11-Sheet2!$H$526)^2+(I11-Sheet2!$I$526)^2+(J11-Sheet2!$J$526)^2+(K11-Sheet2!$K$526)^2+(L11-Sheet2!$L$526)^2) -> 3.178678 | P11: =IF(N11<=O11, 0, 1) -> 0 | Q11: =IF(P11=Sheet1!$M11, 1, 0) -> 1
A12: ACEH | B12: Aceh Utara | C12: 0.69206026 | D12: 0.12483329 | E12: -0.78238649 | F12: -0.071913616 | G12: -0.24587183 | H12: 0.14908122 | I12: 0.37952583 | J12: 1.2338679 | K12: -1.7205236 | L12: -0.10531036 | N12: =SQRT((C12-Sheet2!$C$525)^2+(D12-Sheet2!$D$525)^2+(E12-Sheet2!$E$525)^2+(F12-Sheet2!$F$525)^2+(G12-Sheet2!$G$525)^2+(H12-Sheet2!$H$525)^2+(I12-Sheet2!$I$525)^2+(J12-Sheet2!$J$525)^2+(K12-Sheet2!$K$525)^2+(L12-Sheet2!$L$525)^2) -> 2.6194385 | O12: =SQRT((C12-Sheet2!$C$526)^2+(D12-Sheet2!$D$526)^2+(E12-Sheet2!$E$526)^2+(F12-Sheet2!$F$526)^2+(G12-Sheet2!$G$526)^2+(H12-Sheet2!$H$526)^2+(I12-Sheet2!$I$526)^2+(J12-Sheet2!$J$526)^2+(K12-Sheet2!$K$526)^2+(L12-Sheet2!$L$526)^2) -> 3.8291579 | P12: =IF(N12<=O12, 0, 1) -> 0 | Q12: =IF(P12=Sheet1!$M12, 1, 0) -> 1
A13: ACEH | B13: Aceh Barat Daya | C13: 0.54577988 | D13: 0.14324662 | E13: -0.6987615 | F13: -0.4524575 | G13: -1.3346876 | H13: -0.61901144 | I13: 0.65046156 | J13: -0.38699242 | K13: -1.808158 | L13: -0.39479617 | N13: =SQRT((C13-Sheet2!$C$525)^2+(D13-Sheet2!$D$525)^2+(E13-Sheet2!$E$525)^2+(F13-Sheet2!$F$525)^2+(G13-Sheet2!$G$525)^2+(H13-Sheet2!$H$525)^2+(I13-Sheet2!$I$525)^2+(J13-Sheet2!$J$525)^2+(K13-Sheet2!$K$525)^2+(L13-Sheet2!$L$525)^2) -> 2.545756 | O13: =SQRT((C13-Sheet2!$C$526)^2+(D13-Sheet2!$D$526)^2+(E13-Sheet2!$E$526)^2+(F13-Sheet2!$F$526)^2+(G13-Sheet2!$G$526)^2+(H13-Sheet2!$H$526)^2+(I13-Sheet2!$I$526)^2+(J13-Sheet2!$J$526)^2+(K13-Sheet2!$K$526)^2+(L13-Sheet2!$L$526)^2) -> 4.8580947 | P13: =IF(N13<=O13, 0, 1) -> 0 | Q13: =IF(P13=Sheet1!$M13, 1, 0) -> 1
... A515: PAPUA | B515: Kota Jayapura | C515: -0.11852089 | D515: 1.9232017 | E515: 1.699102 | F515: 1.568893 | G515: 0.25062816 | H515: 0.43671199 | I515: 0.76266083 | J515: 2.509299 | K515: -0.89425576 | L515: 0.018557378 | N515: =SQRT((C515-Sheet2!$C$525)^2+(D515-Sheet2!$D$525)^2+(E515-Sheet2!$E$525)^2+(F515-Sheet2!$F$525)^2+(G515-Sheet2!$G$525)^2+(H515-Sheet2!$H$525)^2+(I515-Sheet2!$I$525)^2+(J515-Sheet2!$J$525)^2+(K515-Sheet2!$K$525)^2+(L515-Sheet2!$L$525)^2) -> 4.7958085 | O515: =SQRT((C515-Sheet2!$C$526)^2+(D515-Sheet2!$D$526)^2+(E515-Sheet2!$E$526)^2+(F515-Sheet2!$F$526)^2+(G515-Sheet2!$G$526)^2+(H515-Sheet2!$H$526)^2+(I515-Sheet2!$I$526)^2+(J515-Sheet2!$J$526)^2+(K515-Sheet2!$K$526)^2+(L515-Sheet2!$L$526)^2) -> 1.9669738 | P515: =IF(N515<=O515, 0, 1) -> 1 | Q515: =IF(P515=Sheet1!$M515, 1, 0) -> 0
P516: TOTAL AKURASI | Q516: =(SUM(Q2:Q515)/514)*100 -> 64.785992
C519: LAMA
C520: 0.90007363 | D520: 0.64040648 | E520: -1.1703033 | F520: -0.54181599 | G520: -1.2708104 | H520: -0.30391031 | I520: 0.14747735 | J520: 0.24692719 | K520: 0.26377109 | L520: -0.4245028
C521: -0.62580511 | D521: 2.6965614 | E521: 2.41894 | F521: 2.4316646 | G521: 0.54097903 | H521: 1.2215023 | I521: 0.90737239 | J521: 1.4730112 | K521: -1.0116234 | L521: -0.13602044
C524: BARU
C525: =AVERAGEIF($P$2:$P$515, 0, C$2:C$515) -> 0.20846356 | D525: =AVERAGEIF($P$2:$P$515, 0, D$2:D$515) -> -0.34964011 | E525: =AVERAGEIF($P$2:$P$515, 0, E$2:E$515) -> -0.36674518 | F525: =AVERAGEIF($P$2:$P$515, 0, F$2:F$515) -> -0.36825147 | G525: =AVERAGEIF($P$2:$P$515, 0, G$2:G$515) -> -0.2735838 | H525: =AVERAGEIF($P$2:$P$515, 0, H$2:H$515) -> -0.2101702 | I525: =AVERAGEIF($P$2:$P$515, 0, I$2:I$515) -> -0.2171493 | J525: =AVERAGEIF($P$2:$P$515, 0, J$2:J$515) -> -0.33714567 | ... L525: =AVERAGEIF($P$2:$P$515, 0, L$2:L$515) -> -0.22182688
C526: =AVERAGEIF($P$2:$P$515, 1, C$2:C$515) -> -0.69195889 | D526: =AVERAGEIF($P$2:$P$515, 1, D$2:D$515) -> 1.1605701 | E526: =AVERAGEIF($P$2:$P$515, 1, E$2:E$515) -> 1.2173475 | F526: =AVERAGEIF($P$2:$P$515, 1, F$2:F$515) -> 1.2223473 | G526: =AVERAGEIF($P$2:$P$515, 1, G$2:G$515) -> 0.90811428 | H526: =AVERAGEIF($P$2:$P$515, 1, H$2:H$515) -> 0.69762378 | I526: =AVERAGEIF($P$2:$P$515, 1, I$2:I$515) -> 0.72078968 | J526: =AVERAGEIF($P$2:$P$515, 1, J$2:J$515) -> 1.119097 | ... L526: =AVERAGEIF($P$2:$P$515, 1, L$2:L$515) -> 0.7363161

Sheet Sheet4
A1: Provinsi+M22NA1:N506 | B1: Kab/Kota | C1: Persentase Penduduk Miskin (P0) Menurut Kabupaten/Kota (Persen) | D1: Rata-rata Lama Sekolah Penduduk 15+ (Tahun) | E1: Pengeluaran per Kapita Disesuaikan (Ribu Rupiah/Orang/Tahun) | F1: Indeks Pembangunan Manusia | G1: Umur Harapan Hidup (Tahun) | H1: Persentase rumah tangga yang memiliki akses terhadap sanitasi layak | I1: Persentase rumah tangga yang memiliki akses terhadap air minum layak | J1: Tingkat Pengangguran Terbuka | K1: Tingkat Partisipasi Angkatan Kerja | L1: PDRB atas Dasar Harga Konstan menurut Pengeluaran (Rupiah) | N1: JARAK KE C1 | O1: JARAK KE C2 | P1: PREDIKSI | Q1: AKURASI
A2: ACEH | B2: Simeulue | C2: 0.90007363 | D2: 0.64040648 | E2: -1.1703033 | F2: -0.54181599 | G2: -1.2708104 | H2: -0.30391031 | I2: 0.14747735 | J2: 0.24692719 | K2: 0.26377109 | L2: -0.4245028 | N2: =SQRT((C2-Sheet3!$C$525)^2+(D2-Sheet3!$D$525)^2+(E2-Sheet3!$E$525)^2+(F2-Sheet3!$F$525)^2+(G2-Sheet3!$G$525)^2+(H2-Sheet3!$H$525)^2+(I2-Sheet3!$I$525)^2+(J2-Sheet3!$J$525)^2+(K2-Sheet3!$K$525)^2+(L2-Sheet3!$L$525)^2) -> 1.9132136 | O2: =SQRT((C2-Sheet3!$C$526)^2+(D2-Sheet3!$D$526)^2+(E2-Sheet3!$E$526)^2+(F2-Sheet3!$F$526)^2+(G2-Sheet3!$G$526)^2+(H2-Sheet3!$H$526)^2+(I2-Sheet3!$I$526)^2+(J2-Sheet3!$J$526)^2+(K2-Sheet3!$K$526)^2+(L2-Sheet3!$L$526)^2) -> 4.5307487 | P2: =IF(N2<=O2, 0, 1) -> 0 | Q2: =IF(P2=Sheet1!M2, 1, 0) -> 1
A3: ACEH | B3: Aceh Singkil | C3: 1.0852726 | D3: 0.14938439 | E3: -0.57056109 | F3: -0.10888954 | G3: -0.64655602 | H3: -0.41163719 | I3: -0.41798147 | J3: 1.2528475 | K3: -1.0350969 | L3: -0.42173791 | N3: =SQRT((C3-Sheet3!$C$525)^2+(D3-Sheet3!$D$525)^2+(E3-Sheet3!$E$525)^2+(F3-Sheet3!$F$525)^2+(G3-Sheet3!$G$525)^2+(H3-Sheet3!$H$525)^2+(I3-Sheet3!$I$525)^2+(J3-Sheet3!$J$525)^2+(K3-Sheet3!$K$525)^2+(L3-Sheet3!$L$525)^2) -> 2.3200463 | O3: =SQRT((C3-Sheet3!$C$526)^2+(D3-Sheet3!$D$526)^2+(E3-Sheet3!$E$526)^2+(F3-Sheet3!$F$526)^2+(G3-Sheet3!$G$526)^2+(H3-Sheet3!$H$526)^2+(I3-Sheet3!$I$526)^2+(J3-Sheet3!$J$526)^2+(K3-Sheet3!$K$526)^2+(L3-Sheet3!$L$526)^2) -> 3.9566368 | P3: =IF(N3<=O3, 0, 1) -> 0 | Q3: =IF(P3=Sheet1!M3, 1, 0) -> 0
A4: ACEH | B4: Aceh Selatan | C4: 0.12170101 | D4: 0.27213991 | E4: -0.79012272 | F4: -0.38312764 | G4: -1.5263192 | H4: -0.78921991 | I4: -0.34976941 | J4: 0.53162163 | K4: -1.3480771 | L4: -0.36813456 | N4: =SQRT((C4-Sheet3!$C$525)^2+(D4-Sheet3!$D$525)^2+(E4-Sheet3!$E$525)^2+(F4-Sheet3!$F$525)^2+(G4-Sheet3!$G$525)^2+(H4-Sheet3!$H$525)^2+(I4-Sheet3!$I$525)^2+(J4-Sheet3!$J$525)^2+(K4-Sheet3!$K$525)^2+(L4-Sheet3!$L$525)^2) -> 2.3656435 | O4: =SQRT((C4-Sheet3!$C$526)^2+(D4-Sheet3!$D$526)^2+(E4-Sheet3!$E$526)^2+(F4-Sheet3!$F$526)^2+(G4-Sheet3!$G$526)^2+(H4-Sheet3!$H$526)^2+(I4-Sheet3!$I$526)^2+(J4-Sheet3!$J$526)^2+(K4-Sheet3!$K$526)^2+(L4-Sheet3!$L$526)^2) -> 4.4145362 | P4: =IF(N4<=O4, 0, 1) -> 0 | Q4: =IF(P4=Sheet1!M4, 1, 0) -> 1
A5: ACEH | B5: Aceh Tenggara | C5: 0.15256751 | D5: 0.75702422 | E5: -0.84538152 | F5: -0.074994943 | G5: -0.41717884 | H5: -0.78060176 | I5: 0.10030265 | J5: 0.52023385 | K5: 0.024341215 | L5: -0.38607559 | N5: =SQRT((C5-Sheet3!$C$525)^2+(D5-Sheet3!$D$525)^2+(E5-Sheet3!$E$525)^2+(F5-Sheet3!$F$525)^2+(G5-Sheet3!$G$525)^2+(H5-Sheet3!$H$525)^2+(I5-Sheet3!$I$525)^2+(J5-Sheet3!$J$525)^2+(K5-Sheet3!$K$525)^2+(L5-Sheet3!$L$525)^2) -> 1.6658129 | O5: =SQRT((C5-Sheet3!$C$526)^2+(D5-Sheet3!$D$526)^2+(E5-Sheet3!$E$526)^2+(F5-Sheet3!$F$526)^2+(G5-Sheet3!$G$526)^2+(H5-Sheet3!$H$526)^2+(I5-Sheet3!$I$526)^2+(J5-Sheet3!$J$526)^2+(K5-Sheet3!$K$526)^2+(L5-Sheet3!$L$526)^2) -> 3.6237045 | P5: =IF(N5<=O5, 0, 1) -> 0 | Q5: =IF(P5=Sheet1!M5, 1, 0) -> 1
A6: ACEH | B6: Aceh Timur | C6: 0.29213777 | D6: -0.13909108 | E6: -0.6438711 | F6: -0.32304177 | G6: -0.26619639 | H6: -0.56299346 | I6: -0.12600837 | J6: 0.78594866 | K6: -1.5624686 | L6: -0.28272112 | N6: =SQRT((C6-Sheet3!$C$525)^2+(D6-Sheet3!$D$525)^2+(E6-Sheet3!$E$525)^2+(F6-Sheet3!$F$525)^2+(G6-Sheet3!$G$525)^2+(H6-Sheet3!$H$525)^2+(I6-Sheet3!$I$525)^2+(J6-Sheet3!$J$525)^2+(K6-Sheet3!$K$525)^2+(L6-Sheet3!$L$525)^2) -> 2.1335422 | O6: =SQRT((C6-Sheet3!$C$526)^2+(D6-Sheet3!$D$526)^2+(E6-Sheet3!$E$526)^2+(F6-Sheet3!$F$526)^2+(G6-Sheet3!$G$526)^2+(H6-Sheet3!$H$526)^2+(I6-Sheet3!$I$526)^2+(J6-Sheet3!$J$526)^2+(K6-Sheet3!$K$526)^2+(L6-Sheet3!$L$526)^2) -> 3.7813343 | P6: =IF(N6<=O6, 0, 1) -> 0 | Q6: =IF(P6=Sheet1!M6, 1, 0) -> 1
A7: ACEH | B7: Aceh Tengah | C7: 0.40084153 | D7: 0.87364196 | E7: 0.16769648 | F7: 0.53048581 | G7: -0.23135428 | H7: 0.72057232 | I7: 0.31641374 | J7: -0.92980981 | K7: 1.0696952 | L7: -0.33454929 | N7: =SQRT((C7-Sheet3!$C$525)^2+(D7-Sheet3!$D$525)^2+(E7-Sheet3!$E$525)^2+(F7-Sheet3!$F$525)^2+(G7-Sheet3!$G$525)^2+(H7-Sheet3!$H$525)^2+(I7-Sheet3!$I$525)^2+(J7-Sheet3!$J$525)^2+(K7-Sheet3!$K$525)^2+(L7-Sheet3!$L$525)^2) -> 2.2229113 | O7: =SQRT((C7-Sheet3!$C$526)^2+(D7-Sheet3!$D$526)^2+(E7-Sheet3!$E$526)^2+(F7-Sheet3!$F$526)^2+(G7-Sheet3!$G$526)^2+(H7-Sheet3!$H$526)^2+(I7-Sheet3!$I$526)^2+(J7-Sheet3!$J$526)^2+(K7-Sheet3!$K$526)^2+(L7-Sheet3!$L$526)^2) -> 3.5220456 | P7: =IF(N7<=O7, 0, 1) -> 0 | Q7: =IF(P7=Sheet1!M7, 1, 0) -> 1
A8: ACEH | B8: Aceh Barat | C8: 0.87725926 | D8: 0.68337091 | E8: -0.26958482 | F8: 0.26857302 | G8: -0.48395954 | H8: 0.66778615 | I8: 0.57906203 | J8: 0.77076495 | K8: -1.4732692 | L8: -0.3025226 | N8: =SQRT((C8-Sheet3!$C$525)^2+(D8-Sheet3!$D$525)^2+(E8-Sheet3!$E$525)^2+(F8-Sheet3!$F$525)^2+(G8-Sheet3!$G$525)^2+(H8-Sheet3!$H$525)^2+(I8-Sheet3!$I$525)^2+(J8-Sheet3!$J$525)^2+(K8-Sheet3!$K$525)^2+(L8-Sheet3!$L$525)^2) -> 2.708144 | O8: =SQRT((C8-Sheet3!$C$526)^2+(D8-Sheet3!$D$526)^2+(E8-Sheet3!$E$526)^2+(F8-Sheet3!$F$526)^2+(G8-Sheet3!$G$526)^2+(H8-Sheet3!$H$526)^2+(I8-Sheet3!$I$526)^2+(J8-Sheet3!$J$526)^2+(K8-Sheet3!$K$526)^2+(L8-Sheet3!$L$526)^2) -> 3.1237496 | P8: =IF(N8<=O8, 0, 1) -> 0 | Q8: =IF(P8=Sheet1!M8, 1, 0) -> 1
A9: ACEH | B9: Aceh Besar | C9: 0.2384569 | D9: 1.1621174 | E9: -0.25079683 | F9: 0.56283975 | G9: 0.038672024 | H9: 0.54928658 | I9: -0.17700804 | J9: 1.0023164 | K9: -1.2197552 | L9: -0.24452379 | N9: =SQRT((C9-Sheet3!$C$525)^2+(D9-Sheet3!$D$525)^2+(E9-Sheet3!$E$525)^2+(F9-Sheet3!$F$525)^2+(G9-Sheet3!$G$525)^2+(H9-Sheet3!$H$525)^2+(I9-Sheet3!$I$525)^2+(J9-Sheet3!$J$525)^2+(K9-Sheet3!$K$525)^2+(L9-Sheet3!$L$525)^2) -> 2.7543991 | O9: =SQRT((C9-Sheet3!$C$526)^2+(D9-Sheet3!$D$526)^2+(E9-Sheet3!$E$526)^2+(F9-Sheet3!$F$526)^2+(G9-Sheet3!$G$526)^2+(H9-Sheet3!$H$526)^2+(I9-Sheet3!$I$526)^2+(J9-Sheet3!$J$526)^2+(K9-Sheet3!$K$526)^2+(L9-Sheet3!$L$526)^2) -> 2.533308 | P9: =IF(N9<=O9, 0, 1) -> 1 | Q9: =IF(P9=Sheet1!M9, 1, 0) -> 0
A10: ACEH | B10: Pidie | C10: 0.98193696 | D10: 0.34579323 | E10: -0.17122416 | F10: 0.11912866 | G10: -0.78592444 | H10: -1.244366 | I10: 0.2615891 | J10: 0.84288754 | K10: -1.4357116 | L10: -0.29229996 | N10: =SQRT((C10-Sheet3!$C$525)^2+(D10-Sheet3!$D$525)^2+(E10-Sheet3!$E$525)^2+(F10-Sheet3!$F$525)^2+(G10-Sheet3!$G$525)^2+(H10-Sheet3!$H$525)^2+(I10-Sheet3!$I$525)^2+(J10-Sheet3!$J$525)^2+(K10-Sheet3!$K$525)^2+(L10-Sheet3!$L$525)^2) -> 2.6297336 | O10: =SQRT((C10-Sheet3!$C$526)^2+(D10-Sheet3!$D$526)^2+(E10-Sheet3!$E$526)^2+(F10-Sheet3!$F$526)^2+(G10-Sheet3!$G$526)^2+(H10-Sheet3!$H$526)^2+(I10-Sheet3!$I$526)^2+(J10-Sheet3!$J$526)^2+(K10-Sheet3!$K$526)^2+(L10-Sheet3!$L$526)^2) -> 3.9140367 | P10: =IF(N10<=O10, 0, 1) -> 0 | Q10: =IF(P10=Sheet1!M10, 1, 0) -> 1
A11: ACEH | B11: Bireuen | C11: 0.13109516 | D11: 0.52378873 | E11: -0.53703742 | F11: 0.37025681 | G11: 0.4654878 | H11: 0.25249902 | I11: 0.53507482 | J11: -0.2807065 | K11: -0.55623711 | L11: -0.24216485 | N11: =SQRT((C11-Sheet3!$C$525)^2+(D11-Sheet3!$D$525)^2+(E11-Sheet3!$E$525)^2+(F11-Sheet3!$F$525)^2+(G11-Sheet3!$G$525)^2+(H11-Sheet3!$H$525)^2+(I11-Sheet3!$I$525)^2+(J11-Sheet3!$J$525)^2+(K11-Sheet3!$K$525)^2+(L11-Sheet3!$L$525)^2) -> 1.7916076 | O11: =SQRT((C11-Sheet3!$C$526)^2+(D11-Sheet3!$D$526)^2+(E11-Sheet3!$E$526)^2+(F11-Sheet3!$F$526)^2+(G11-Sheet3!$G$526)^2+(H11-Sheet3!$H$526)^2+(I11-Sheet3!$I$526)^2+(J11-Sheet3!$J$526)^2+(K11-Sheet3!$K$526)^2+(L11-Sheet3!$L$526)^2) -> 2.8693423 | P11: =IF(N11<=O11, 0, 1) -> 0 | Q11: =IF(P11=Sheet1!M11, 1, 0) -> 1
A12: ACEH | B12: Aceh Utara | C12: 0.69206026 | D12: 0.12483329 | E12: -0.78238649 | F12: -0.071913616 | G12: -0.24587183 | H12: 0.14908122 | I12: 0.37952583 | J12: 1.2338679 | K12: -1.7205236 | L12: -0.10531036 | N12: =SQRT((C12-Sheet3!$C$525)^2+(D12-Sheet3!$D$525)^2+(E12-Sheet3!$E$525)^2+(F12-Sheet3!$F$525)^2+(G12-Sheet3!$G$525)^2+(H12-Sheet3!$H$525)^2+(I12-Sheet3!$I$525)^2+(J12-Sheet3!$J$525)^2+(K12-Sheet3!$K$525)^2+(L12-Sheet3!$L$525)^2) -> 2.6992013 | O12: =SQRT((C12-Sheet3!$C$526)^2+(D12-Sheet3!$D$526)^2+(E12-Sheet3!$E$526)^2+(F12-Sheet3!$F$526)^2+(G12-Sheet3!$G$526)^2+(H12-Sheet3!$H$526)^2+(I12-Sheet3!$I$526)^2+(J12-Sheet3!$J$526)^2+(K12-Sheet3!$K$526)^2+(L12-Sheet3!$L$526)^2) -> 3.5242712 | P12: =IF(N12<=O12, 0, 1) -> 0 | Q12: =IF(P12=Sheet1!M12, 1, 0) -> 1
A13: ACEH | B13: Aceh Barat Daya | C13: 0.54577988 | D13: 0.14324662 | E13: -0.6987615 | F13: -0.4524575 | G13: -1.3346876 | H13: -0.61901144 | I13: 0.65046156 | J13: -0.38699242 | K13: -1.808158 | L13: -0.39479617 | N13: =SQRT((C13-Sheet3!$C$525)^2+(D13-Sheet3!$D$525)^2+(E13-Sheet3!$E$525)^2+(F13-Sheet3!$F$525)^2+(G13-Sheet3!$G$525)^2+(H13-Sheet3!$H$525)^2+(I13-Sheet3!$I$525)^2+(J13-Sheet3!$J$525)^2+(K13-Sheet3!$K$525)^2+(L13-Sheet3!$L$525)^2) -> 2.5477572 | O13: =SQRT((C13-Sheet3!$C$526)^2+(D13-Sheet3!$D$526)^2+(E13-Sheet3!$E$526)^2+(F13-Sheet3!$F$526)^2+(G13-Sheet3!$G$526)^2+(H13-Sheet3!$H$526)^2+(I13-Sheet3!$I$526)^2+(J13-Sheet3!$J$526)^2+(K13-Sheet3!$K$526)^2+(L13-Sheet3!$L$526)^2) -> 4.5666111 | P13: =IF(N13<=O13, 0, 1) -> 0 | Q13: =IF(P13=Sheet1!M13, 1, 0) -> 1
... A515: PAPUA | B515: Kota Jayapura | C515: -0.11852089 | D515: 1.9232017 | E515: 1.699102 | F515: 1.568893 | G515: 0.25062816 | H515: 0.43671199 | I515: 0.76266083 | J515: 2.509299 | K515: -0.89425576 | L515: 0.018557378 | N515: =SQRT((C515-Sheet3!$C$525)^2+(D515-Sheet3!$D$525)^2+(E515-Sheet3!$E$525)^2+(F515-Sheet3!$F$525)^2+(G515-Sheet3!$G$525)^2+(H515-Sheet3!$H$525)^2+(I515-Sheet3!$I$525)^2+(J515-Sheet3!$J$525)^2+(K515-Sheet3!$K$525)^2+(L515-Sheet3!$L$525)^2) -> 4.9247097 | O515: =SQRT((C515-Sheet3!$C$526)^2+(D515-Sheet3!$D$526)^2+(E515-Sheet3!$E$526)^2+(F515-Sheet3!$F$526)^2+(G515-Sheet3!$G$526)^2+(H515-Sheet3!$H$526)^2+(I515-Sheet3!$I$526)^2+(J515-Sheet3!$J$526)^2+(K515-Sheet3!$K$526)^2+(L515-Sheet3!$L$526)^2) -> 2.0755068 | P515: =IF(N515<=O515, 0, 1) -> 1 | Q515: =IF(P515=Sheet1!M515, 1, 0) -> 0
P516: TOTAL AKURASI | Q516: =(SUM(Q2:Q515)/514)*100 -> 61.478599
C519: LAMA
C520: 0.20846356 | D520: -0.34964011 | E520: -0.36674518 | F520: -0.36825147 | G520: -0.2735838 | H520: -0.2101702 | I520: -0.2171493 | J520: -0.33714567 | K520: 0.17647734 | L520: -0.22182688
C521: -0.69195889 | D521: 1.1605701 | E521: 1.2173475 | F521: 1.2223473 | G521: 0.90811428 | H521: 0.69762378 | I521: 0.72078968 | J521: 1.119097 | K521: -0.58578613 | L521: 0.7363161
C524: BARU
C525: =AVERAGEIF($P$2:$P$515, 0, C$2:C$515) -> 0.23302846 | D525: =AVERAGEIF($P$2:$P$515, 0, D$2:D$515) -> -0.36977728 | E525: =AVERAGEIF($P$2:$P$515, 0, E$2:E$515) -> -0.39744316 | F525: =AVERAGEIF($P$2:$P$515, 0, F$2:F$515) -> -0.40120395 | G525: =AVERAGEIF($P$2:$P$515, 0, G$2:G$515) -> -0.31399674 | H525: =AVERAGEIF($P$2:$P$515, 0, H$2:H$515) -> -0.24026738 | I525: =AVERAGEIF($P$2:$P$515, 0, I$2:I$515) -> -0.25279584 | J525: =AVERAGEIF($P$2:$P$515, 0, J$2:J$515) -> -0.38060563 | ... L525: =AVERAGEIF($P$2:$P$515, 0, L$2:L$515) -> -0.23051323
C526: =AVERAGEIF($P$2:$P$515, 1, C$2:C$515) -> -0.64768204 | D526: =AVERAGEIF($P$2:$P$515, 1, D$2:D$515) -> 1.0277633 | E526: =AVERAGEIF($P$2:$P$515, 1, E$2:E$515) -> 1.1046582 | F526: =AVERAGEIF($P$2:$P$515, 1, F$2:F$515) -> 1.115111 | G526: =AVERAGEIF($P$2:$P$515, 1, G$2:G$515) -> 0.87272624 | H526: =AVERAGEIF($P$2:$P$515, 1, H$2:H$515) -> 0.66780199 | I526: =AVERAGEIF($P$2:$P$515, 1, I$2:I$515) -> 0.70262372 | J526: =AVERAGEIF($P$2:$P$515, 1, J$2:J$515) -> 1.0578598 | ... L526: =AVERAGEIF($P$2:$P$515, 1, L$2:L$515) -> 0.64069118

Sheet Sheet5
A1: Provinsi+M22NA1:N506 | B1: Kab/Kota | C1: Persentase Penduduk Miskin (P0) Menurut Kabupaten/Kota (Persen) | D1: Rata-rata Lama Sekolah Penduduk 15+ (Tahun) | E1: Pengeluaran per Kapita Disesuaikan (Ribu Rupiah/Orang/Tahun) | F1: Indeks Pembangunan Manusia | G1: Umur Harapan Hidup (Tahun) | H1: Persentase rumah tangga yang memiliki akses terhadap sanitasi layak | I1: Persentase rumah tangga yang memiliki akses terhadap air minum layak | J1: Tingkat Pengangguran Terbuka | K1: Tingkat Partisipasi Angkatan Kerja | L1: PDRB atas Dasar Harga Konstan menurut Pengeluaran (Rupiah) | N1: JARAK KE C1 | O1: JARAK KE C2 | P1: PREDIKSI | Q1: AKURASI
A2: ACEH | B2: Simeulue | C2: 0.90007363 | D2: 0.64040648 | E2: -1.1703033 | F2: -0.54181599 | G2: -1.2708104 | H2: -0.30391031 | I2: 0.14747735 | J2: 0.24692719 | K2: 0.26377109 | L2: -0.4245028 | N2: =SQRT((C2-Sheet4!$C$525)^2+(D2-Sheet4!$D$525)^2+(E2-Sheet4!$E$525)^2+(F2-Sheet4!$F$525)^2+(G2-Sheet4!$G$525)^2+(H2-Sheet4!$H$525)^2+(I2-Sheet4!$I$525)^2+(J2-Sheet4!$J$525)^2+(K2-Sheet4!$K$525)^2+(L2-Sheet4!$L$525)^2) -> 1.8965515 | O2: =SQRT((C2-Sheet4!$C$526)^2+(D2-Sheet4!$D$526)^2+(E2-Sheet4!$E$526)^2+(F2-Sheet4!$F$526)^2+(G2-Sheet4!$G$526)^2+(H2-Sheet4!$H$526)^2+(I2-Sheet4!$I$526)^2+(J2-Sheet4!$J$526)^2+(K2-Sheet4!$K$526)^2+(L2-Sheet4!$L$526)^2) -> 4.3370991 | P2: =IF(N2<=O2, 0, 1) -> 0 | Q2: =IF(P2=Sheet1!$M2, 1, 0) -> 1
A3: ACEH | B3: Aceh Singkil | C3: 1.0852726 | D3: 0.14938439 | E3: -0.57056109 | F3: -0.10888954 | G3: -0.64655602 | H3: -0.41163719 | I3: -0.41798147 | J3: 1.2528475 | K3: -1.0350969 | L3: -0.42173791 | N3: =SQRT((C3-Sheet4!$C$525)^2+(D3-Sheet4!$D$525)^2+(E3-Sheet4!$E$525)^2+(F3-Sheet4!$F$525)^2+(G3-Sheet4!$G$525)^2+(H3-Sheet4!$H$525)^2+(I3-Sheet4!$I$525)^2+(J3-Sheet4!$J$525)^2+(K3-Sheet4!$K$525)^2+(L3-Sheet4!$L$525)^2) -> 2.3508091 | O3: =SQRT((C3-Sheet4!$C$526)^2+(D3-Sheet4!$D$526)^2+(E3-Sheet4!$E$526)^2+(F3-Sheet4!$F$526)^2+(G3-Sheet4!$G$526)^2+(H3-Sheet4!$H$526)^2+(I3-Sheet4!$I$526)^2+(J3-Sheet4!$J$526)^2+(K3-Sheet4!$K$526)^2+(L3-Sheet4!$L$526)^2) -> 3.7664681 | P3: =IF(N3<=O3, 0, 1) -> 0 | Q3: =IF(P3=Sheet1!$M3, 1, 0) -> 0
A4: ACEH | B4: Aceh Selatan | C4: 0.12170101 | D4: 0.27213991 | E4: -0.79012272 | F4: -0.38312764 | G4: -1.5263192 | H4: -0.78921991 | I4: -0.34976941 | J4: 0.53162163 | K4: -1.3480771 | L4: -0.36813456 | N4: =SQRT((C4-Sheet4!$C$525)^2+(D4-Sheet4!$D$525)^2+(E4-Sheet4!$E$525)^2+(F4-Sheet4!$F$525)^2+(G4-Sheet4!$G$525)^2+(H4-Sheet4!$H$525)^2+(I4-Sheet4!$I$525)^2+(J4-Sheet4!$J$525)^2+(K4-Sheet4!$K$525)^2+(L4-Sheet4!$L$525)^2) -> 2.3725779 | O4: =SQRT((C4-Sheet4!$C$526)^2+(D4-Sheet4!$D$526)^2+(E4-Sheet4!$E$526)^2+(F4-Sheet4!$F$526)^2+(G4-Sheet4!$G$526)^2+(H4-Sheet4!$H$526)^2+(I4-Sheet4!$I$526)^2+(J4-Sheet4!$J$526)^2+(K4-Sheet4!$K$526)^2+(L4-Sheet4!$L$526)^2) -> 4.2278894 | P4: =IF(N4<=O4, 0, 1) -> 0 | Q4: =IF(P4=Sheet1!$M4, 1, 0) -> 1
A5: ACEH | B5: Aceh Tenggara | C5: 0.15256751 | D5: 0.75702422 | E5: -0.84538152 | F5: -0.074994943 | G5: -0.41717884 | H5: -0.78060176 | I5: 0.10030265 | J5: 0.52023385 | K5: 0.024341215 | L5: -0.38607559 | N5: =SQRT((C5-Sheet4!$C$525)^2+(D5-Sheet4!$D$525)^2+(E5-Sheet4!$E$525)^2+(F5-Sheet4!$F$525)^2+(G5-Sheet4!$G$525)^2+(H5-Sheet4!$H$525)^2+(I5-Sheet4!$I$525)^2+(J5-Sheet4!$J$525)^2+(K5-Sheet4!$K$525)^2+(L5-Sheet4!$L$525)^2) -> 1.6969428 | O5: =SQRT((C5-Sheet4!$C$526)^2+(D5-Sheet4!$D$526)^2+(E5-Sheet4!$E$526)^2+(F5-Sheet4!$F$526)^2+(G5-Sheet4!$G$526)^2+(H5-Sheet4!$H$526)^2+(I5-Sheet4!$I$526)^2+(J5-Sheet4!$J$526)^2+(K5-Sheet4!$K$526)^2+(L5-Sheet4!$L$526)^2) -> 3.4293532 | P5: =IF(N5<=O5, 0, 1) -> 0 | Q5: =IF(P5=Sheet1!$M5, 1, 0) -> 1
A6: ACEH | B6: Aceh Timur | C6: 0.29213777 | D6: -0.13909108 | E6: -0.6438711 | F6: -0.32304177 | G6: -0.26619639 | H6: -0.56299346 | I6: -0.12600837 | J6: 0.78594866 | K6: -1.5624686 | L6: -0.28272112 | N6: =SQRT((C6-Sheet4!$C$525)^2+(D6-Sheet4!$D$525)^2+(E6-Sheet4!$E$525)^2+(F6-Sheet4!$F$525)^2+(G6-Sheet4!$G$525)^2+(H6-Sheet4!$H$525)^2+(I6-Sheet4!$I$525)^2+(J6-Sheet4!$J$525)^2+(K6-Sheet4!$K$525)^2+(L6-Sheet4!$L$525)^2) -> 2.1773845 | O6: =SQRT((C6-Sheet4!$C$526)^2+(D6-Sheet4!$D$526)^2+(E6-Sheet4!$E$526)^2+(F6-Sheet4!$F$526)^2+(G6-Sheet4!$G$526)^2+(H6-Sheet4!$H$526)^2+(I6-Sheet4!$I$526)^2+(J6-Sheet4!$J$526)^2+(K6-Sheet4!$K$526)^2+(L6-Sheet4!$L$526)^2) -> 3.5734562 | P6: =IF(N6<=O6, 0, 1) -> 0 | Q6: =IF(P6=Sheet1!$M6, 1, 0) -> 1
A7: ACEH | B7: Aceh Tengah | C7: 0.40084153 | D7: 0.87364196 | E7: 0.16769648 | F7: 0.53048581 | G7: -0.23135428 | H7: 0.72057232 | I7: 0.31641374 | J7: -0.92980981 | K7: 1.0696952 | L7: -0.33454929 | N7: =SQRT((C7-Sheet4!$C$525)^2+(D7-Sheet4!$D$525)^2+(E7-Sheet4!$E$525)^2+(F7-Sheet4!$F$525)^2+(G7-Sheet4!$G$525)^2+(H7-Sheet4!$H$525)^2+(I7-Sheet4!$I$525)^2+(J7-Sheet4!$J$525)^2+(K7-Sheet4!$K$525)^2+(L7-Sheet4!$L$525)^2) -> 2.2521643 | O7: =SQRT((C7-Sheet4!$C$526)^2+(D7-Sheet4!$D$526)^2+(E7-Sheet4!$E$526)^2+(F7-Sheet4!$F$526)^2+(G7-Sheet4!$G$526)^2+(H7-Sheet4!$H$526)^2+(I7-Sheet4!$I$526)^2+(J7-Sheet4!$J$526)^2+(K7-Sheet4!$K$526)^2+(L7-Sheet4!$L$526)^2) -> 3.3649284 | P7: =IF(N7<=O7, 0, 1) -> 0 | Q7: =IF(P7=Sheet1!$M7, 1, 0) -> 1
A8: ACEH | B8: Aceh Barat | C8: 0.87725926 | D8: 0.68337091 | E8: -0.26958482 | F8: 0.26857302 | G8: -0.48395954 | H8: 0.66778615 | I8: 0.57906203 | J8: 0.77076495 | K8: -1.4732692 | L8: -0.3025226 | N8: =SQRT((C8-Sheet4!$C$525)^2+(D8-Sheet4!$D$525)^2+(E8-Sheet4!$E$525)^2+(F8-Sheet4!$F$525)^2+(G8-Sheet4!$G$525)^2+(H8-Sheet4!$H$525)^2+(I8-Sheet4!$I$525)^2+(J8-Sheet4!$J$525)^2+(K8-Sheet4!$K$525)^2+(L8-Sheet4!$L$525)^2) -> 2.7729077 | O8: =SQRT((C8-Sheet4!$C$526)^2+(D8-Sheet4!$D$526)^2+(E8-Sheet4!$E$526)^2+(F8-Sheet4!$F$526)^2+(G8-Sheet4!$G$526)^2+(H8-Sheet4!$H$526)^2+(I8-Sheet4!$I$526)^2+(J8-Sheet4!$J$526)^2+(K8-Sheet4!$K$526)^2+(L8-Sheet4!$L$526)^2) -> 2.9466839 | P8: =IF(N8<=O8, 0, 1) -> 0 | Q8: =IF(P8=Sheet1!$M8, 1, 0) -> 1
A9: ACEH | B9: Aceh Besar | C9: 0.2384569 | D9: 1.1621174 | E9: -0.25079683 | F9: 0.56283975 | G9: 0.038672024 | H9: 0.54928658 | I9: -0.17700804 | J9: 1.0023164 | K9: -1.2197552 | L9: -0.24452379 | N9: =SQRT((C9-Sheet4!$C$525)^2+(D9-Sheet4!$D$525)^2+(E9-Sheet4!$E$525)^2+(F9-Sheet4!$F$525)^2+(G9-Sheet4!$G$525)^2+(H9-Sheet4!$H$525)^2+(I9-Sheet4!$I$525)^2+(J9-Sheet4!$J$525)^2+(K9-Sheet4!$K$525)^2+(L9-Sheet4!$L$525)^2) -> 2.8283766 | O9: =SQRT((C9-Sheet4!$C$526)^2+(D9-Sheet4!$D$526)^2+(E9-Sheet4!$E$526)^2+(F9-Sheet4!$F$526)^2+(G9-Sheet4!$G$526)^2+(H9-Sheet4!$H$526)^2+(I9-Sheet4!$I$526)^2+(J9-Sheet4!$J$526)^2+(K9-Sheet4!$K$526)^2+(L9-Sheet4!$L$526)^2) -> 2.3728901 | P9: =IF(N9<=O9, 0, 1) -> 1 | Q9: =IF(P9=Sheet1!$M9, 1, 0) -> 0
A10: ACEH | B10: Pidie | C10: 0.98193696 | D10: 0.34579323 | E10: -0.17122416 | F10: 0.11912866 | G10: -0.78592444 | H10: -1.244366 | I10: 0.2615891 | J10: 0.84288754 | K10: -1.4357116 | L10: -0.29229996 | N10: =SQRT((C10-Sheet4!$C$525)^2+(D10-Sheet4!$D$525)^2+(E10-Sheet4!$E$525)^2+(F10-Sheet4!$F$525)^2+(G10-Sheet4!$G$525)^2+(H10-Sheet4!$H$525)^2+(I10-Sheet4!$I$525)^2+(J10-Sheet4!$J$525)^2+(K10-Sheet4!$K$525)^2+(L10-Sheet4!$L$525)^2) -> 2.662692 | O10: =SQRT((C10-Sheet4!$C$526)^2+(D10-Sheet4!$D$526)^2+(E10-Sheet4!$E$526)^2+(F10-Sheet4!$F$526)^2+(G10-Sheet4!$G$526)^2+(H10-Sheet4!$H$526)^2+(I10-Sheet4!$I$526)^2+(J10-Sheet4!$J$526)^2+(K10-Sheet4!$K$526)^2+(L10-Sheet4!$L$526)^2) -> 3.7415332 | P10: =IF(N10<=O10, 0, 1) -> 0 | Q10: =IF(P10=Sheet1!$M10, 1, 0) -> 1
A11: ACEH | B11: Bireuen | C11: 0.13109516 | D11: 0.52378873 | E11: -0.53703742 | F11: 0.37025681 | G11: 0.4654878 | H11: 0.25249902 | I11: 0.53507482 | J11: -0.2807065 | K11: -0.55623711 | L11: -0.24216485 | N11: =SQRT((C11-Sheet4!$C$525)^2+(D11-Sheet4!$D$525)^2+(E11-Sheet4!$E$525)^2+(F11-Sheet4!$F$525)^2+(G11-Sheet4!$G$525)^2+(H11-Sheet4!$H$525)^2+(I11-Sheet4!$I$525)^2+(J11-Sheet4!$J$525)^2+(K11-Sheet4!$K$525)^2+(L11-Sheet4!$L$525)^2) -> 1.8674694 | O11: =SQRT((C11-Sheet4!$C$526)^2+(D11-Sheet4!$D$526)^2+(E11-Sheet4!$E$526)^2+(F11-Sheet4!$F$526)^2+(G11-Sheet4!$G$526)^2+(H11-Sheet4!$H$526)^2+(I11-Sheet4!$I$526)^2+(J11-Sheet4!$J$526)^2+(K11-Sheet4!$K$526)^2+(L11-Sheet4!$L$526)^2) -> 2.6548858 | P11: =IF(N11<=O11, 0, 1) -> 0 | Q11: =IF(P11=Sheet1!$M11, 1, 0) -> 1
A12: ACEH | B12: Aceh Utara | C12: 0.69206026 | D12: 0.12483329 | E12: -0.78238649 | F12: -0.071913616 | G12: -0.24587183 | H12: 0.14908122 | I12: 0.37952583 | J12: 1.2338679 | K12: -1.7205236 | L12: -0.10531036 | N12: =SQRT((C12-Sheet4!$C$525)^2+(D12-Sheet4!$D$525)^2+(E12-Sheet4!$E$525)^2+(F12-Sheet4!$F$525)^2+(G12-Sheet4!$G$525)^2+(H12-Sheet4!$H$525)^2+(I12-Sheet4!$I$525)^2+(J12-Sheet4!$J$525)^2+(K12-Sheet4!$K$525)^2+(L12-Sheet4!$L$525)^2) -> 2.7578901 | O12: =SQRT((C12-Sheet4!$C$526)^2+(D12-Sheet4!$D$526)^2+(E12-Sheet4!$E$526)^2+(F12-Sheet4!$F$526)^2+(G12-Sheet4!$G$526)^2+(H12-Sheet4!$H$526)^2+(I12-Sheet4!$I$526)^2+(J12-Sheet4!$J$526)^2+(K12-Sheet4!$K$526)^2+(L12-Sheet4!$L$526)^2) -> 3.332146 | P12: =IF(N12<=O12, 0, 1) -> 0 | Q12: =IF(P12=Sheet1!$M12, 1, 0) -> 1
A13: ACEH | B13: Aceh Barat Daya | C13: 0.54577988 | D13: 0.14324662 | E13: -0.6987615 | F13: -0.4524575 | G13: -1.3346876 | H13: -0.61901144 | I13: 0.65046156 | J13: -0.38699242 | K13: -1.808158 | L13: -0.39479617 | N13: =SQRT((C13-Sheet4!$C$525)^2+(D13-Sheet4!$D$525)^2+(E13-Sheet4!$E$525)^2+(F13-Sheet4!$F$525)^2+(G13-Sheet4!$G$525)^2+(H13-Sheet4!$H$525)^2+(I13-Sheet4!$I$525)^2+(J13-Sheet4!$J$525)^2+(K13-Sheet4!$K$525)^2+(L13-Sheet4!$L$525)^2) -> 2.5580949 | O13: =SQRT((C13-Sheet4!$C$526)^2+(D13-Sheet4!$D$526)^2+(E13-Sheet4!$E$526)^2+(F13-Sheet4!$F$526)^2+(G13-Sheet4!$G$526)^2+(H13-Sheet4!$H$526)^2+(I13-Sheet4!$I$526)^2+(J13-Sheet4!$J$526)^2+(K13-Sheet4!$K$526)^2+(L13-Sheet4!$L$526)^2) -> 4.3733964 | P13: =IF(N13<=O13, 0, 1) -> 0 | Q13: =IF(P13=Sheet1!$M13, 1, 0) -> 1
... A515: PAPUA | B515: Kota Jayapura | C515: -0.11852089 | D515: 1.9232017 | E515: 1.699102 | F515: 1.568893 | G515: 0.25062816 | H515: 0.43671199 | I515: 0.76266083 | J515: 2.509299 | K515: -0.89425576 | L515: 0.018557378 | N515: =SQRT((C515-Sheet4!$C$525)^2+(D515-Sheet4!$D$525)^2+(E515-Sheet4!$E$525)^2+(F515-Sheet4!$F$525)^2+(G515-Sheet4!$G$525)^2+(H515-Sheet4!$H$525)^2+(I515-Sheet4!$I$525)^2+(J515-Sheet4!$J$525)^2+(K515-Sheet4!$K$525)^2+(L515-Sheet4!$L$525)^2) -> 5.0092859 | O515: =SQRT((C515-Sheet4!$C$526)^2+(D515-Sheet4!$D$526)^2+(E515-Sheet4!$E$526)^2+(F515-Sheet4!$F$526)^2+(G515-Sheet4!$G$526)^2+(H515-Sheet4!$H$526)^2+(I515-Sheet4!$I$526)^2+(J515-Sheet4!$J$526)^2+(K515-Sheet4!$K$526)^2+(L515-Sheet4!$L$526)^2) -> 2.1634174 | P515: =IF(N515<=O515, 0, 1) -> 1 | Q515: =IF(P515=Sheet1!$M515, 1, 0) -> 0
P516: TOTAL AKURASI | Q516: =(SUM(Q2:Q515)/514)*100 -> 58.949416
C519: LAMA
C520: 0.23302846 | D520: -0.36977728 | E520: -0.39744316 | F520: -0.40120395 | G520: -0.31399674 | H520: -0.24026738 | I520: -0.25279584 | J520: -0.38060563 | K520: 0.20709931 | L520: -0.23051323
C521: -0.64768204 | D521: 1.0277633 | E521: 1.1046582 | F521: 1.115111 | G521: 0.87272624 | H521: 0.66780199 | I521: 0.70262372 | J521: 1.0578598 | K521: -0.57561427 | L521: 0.64069118
C524: BARU
C525: =AVERAGEIF($P$2:$P$515, 0, C$2:C$515) -> 0.25757244 | D525: =AVERAGEIF($P$2:$P$515, 0, D$2:D$515) -> -0.37832982 | E525: =AVERAGEIF($P$2:$P$515, 0, E$2:E$515) -> -0.42352524 | F525: =AVERAGEIF($P$2:$P$515, 0, F$2:F$515) -> -0.42745232 | G525: =AVERAGEIF($P$2:$P$515, 0, G$2:G$515) -> -0.35136067 | H525: =AVERAGEIF($P$2:$P$515, 0, H$2:H$515) -> -0.26637414 | I525: =AVERAGEIF($P$2:$P$515, 0, I$2:I$515) -> -0.27791577 | J525: =AVERAGEIF($P$2:$P$515, 0, J$2:J$515) -> -0.40636724 | ... L525: =AVERAGEIF($P$2:$P$515, 0, L$2:L$515) -> -0.23674925
C526: =AVERAGEIF($P$2:$P$515, 1, C$2:C$515) -> -0.63096604 | D526: =AVERAGEIF($P$2:$P$515, 1, D$2:D$515) -> 0.9267811 | E526: =AVERAGEIF($P$2:$P$515, 1, E$2:E$515) -> 1.0374947 | F526: =AVERAGEIF($P$2:$P$515, 1, F$2:F$515) -> 1.0471148 | G526: =AVERAGEIF($P$2:$P$515, 1, G$2:G$515) -> 0.86071574 | H526: =AVERAGEIF($P$2:$P$515, 1, H$2:H$515) -> 0.65252725 | I526: =AVERAGEIF($P$2:$P$515, 1, I$2:I$515) -> 0.68080038 | J526: =AVERAGEIF($P$2:$P$515, 1, J$2:J$515) -> 0.99546338 | ... L526: =AVERAGEIF($P$2:$P$515, 1, L$2:L$515) -> 0.57995621

Sheet Sheet6
A1: Provinsi+M22NA1:N506 | B1: Kab/Kota | C1: Persentase Penduduk Miskin (P0) Menurut Kabupaten/Kota (Persen) | D1: Rata-rata Lama Sekolah Penduduk 15+ (Tahun) | E1: Pengeluaran per Kapita Disesuaikan (Ribu Rupiah/Orang/Tahun) | F1: Indeks Pembangunan Manusia | G1: Umur Harapan Hidup (Tahun) | H1: Persentase rumah tangga yang memiliki akses terhadap sanitasi layak | I1: Persentase rumah tangga yang memiliki akses terhadap air minum layak | J1: Tingkat Pengangguran Terbuka | K1: Tingkat Partisipasi Angkatan Kerja | L1: PDRB atas Dasar Harga Konstan menurut Pengeluaran (Rupiah) | N1: JARAK KE C1 | O1: JARAK KE C2 | P1: PREDIKSI | Q1: AKURASI
A2: ACEH | B2: Simeulue | C2: 0.90007363 | D2: 0.64040648 | E2: -1.1703033 | F2: -0.54181599 | G2: -1.2708104 | H2: -0.30391031 | I2: 0.14747735 | J2: 0.24692719 | K2: 0.26377109 | L2: -0.4245028 | N2: =SQRT((C2-Sheet5!$C$525)^2+(D2-Sheet5!$D$525)^2+(E2-Sheet5!$E$525)^2+(F2-Sheet5!$F$525)^2+(G2-Sheet5!$G$525)^2+(H2-Sheet5!$H$525)^2+(I2-Sheet5!$I$525)^2+(J2-Sheet5!$J$525)^2+(K2-Sheet5!$K$525)^2+(L2-Sheet5!$L$525)^2) -> 1.8741994 | O2: =SQRT((C2-Sheet5!$C$526)^2+(D2-Sheet5!$D$526)^2+(E2-Sheet5!$E$526)^2+(F2-Sheet5!$F$526)^2+(G2-Sheet5!$G$526)^2+(H2-Sheet5!$H$526)^2+(I2-Sheet5!$I$526)^2+(J2-Sheet5!$J$526)^2+(K2-Sheet5!$K$526)^2+(L2-Sheet5!$L$526)^2) -> 4.2195663 | P2: =IF(N2<=O2, 0, 1) -> 0 | Q2: =IF(P2=Sheet1!$M2, 1, 0) -> 1
A3: ACEH | B3: Aceh Singkil | C3: 1.0852726 | D3: 0.14938439 | E3: -0.57056109 | F3: -0.10888954 | G3: -0.64655602 | H3: -0.41163719 | I3: -0.41798147 | J3: 1.2528475 | K3: -1.0350969 | L3: -0.42173791 | N3: =SQRT((C3-Sheet5!$C$525)^2+(D3-Sheet5!$D$525)^2+(E3-Sheet5!$E$525)^2+(F3-Sheet5!$F$525)^2+(G3-Sheet5!$G$525)^2+(H3-Sheet5!$H$525)^2+(I3-Sheet5!$I$525)^2+(J3-Sheet5!$J$525)^2+(K3-Sheet5!$K$525)^2+(L3-Sheet5!$L$525)^2) -> 2.3647092 | O3: =SQRT((C3-Sheet5!$C$526)^2+(D3-Sheet5!$D$526)^2+(E3-Sheet5!$E$526)^2+(F3-Sheet5!$F$526)^2+(G3-Sheet5!$G$526)^2+(H3-Sheet5!$H$526)^2+(I3-Sheet5!$I$526)^2+(J3-Sheet5!$J$526)^2+(K3-Sheet5!$K$526)^2+(L3-Sheet5!$L$526)^2) -> 3.6585987 | P3: =IF(N3<=O3, 0, 1) -> 0 | Q3: =IF(P3=Sheet1!$M3, 1, 0) -> 0
A4: ACEH | B4: Aceh Selatan | C4: 0.12170101 | D4: 0.27213991 | E4: -0.79012272 | F4: -0.38312764 | G4: -1.5263192 | H4: -0.78921991 | I4: -0.34976941 | J4: 0.53162163 | K4: -1.3480771 | L4: -0.36813456 | N4: =SQRT((C4-Sheet5!$C$525)^2+(D4-Sheet5!$D$525)^2+(E4-Sheet5!$E$525)^2+(F4-Sheet5!$F$525)^2+(G4-Sheet5!$G$525)^2+(H4-Sheet5!$H$525)^2+(I4-Sheet5!$I$525)^2+(J4-Sheet5!$J$525)^2+(K4-Sheet5!$K$525)^2+(L4-Sheet5!$L$525)^2) -> 2.3688532 | O4: =SQRT((C4-Sheet5!$C$526)^2+(D4-Sheet5!$D$526)^2+(E4-Sheet5!$E$526)^2+(F4-Sheet5!$F$526)^2+(G4-Sheet5!$G$526)^2+(H4-Sheet5!$H$526)^2+(I4-Sheet5!$I$526)^2+(J4-Sheet5!$J$526)^2+(K4-Sheet5!$K$526)^2+(L4-Sheet5!$L$526)^2) -> 4.1188677 | P4: =IF(N4<=O4, 0, 1) -> 0 | Q4: =IF(P4=Sheet1!$M4, 1, 0) -> 1
A5: ACEH | B5: Aceh Tenggara | C5: 0.15256751 | D5: 0.75702422 | E5: -0.84538152 | F5: -0.074994943 | G5: -0.41717884 | H5: -0.78060176 | I5: 0.10030265 | J5: 0.52023385 | K5: 0.024341215 | L5: -0.38607559 | N5: =SQRT((C5-Sheet5!$C$525)^2+(D5-Sheet5!$D$525)^2+(E5-Sheet5!$E$525)^2+(F5-Sheet5!$F$525)^2+(G5-Sheet5!$G$525)^2+(H5-Sheet5!$H$525)^2+(I5-Sheet5!$I$525)^2+(J5-Sheet5!$J$525)^2+(K5-Sheet5!$K$525)^2+(L5-Sheet5!$L$525)^2) -> 1.7133497 | O5: =SQRT((C5-Sheet5!$C$526)^2+(D5-Sheet5!$D$526)^2+(E5-Sheet5!$E$526)^2+(F5-Sheet5!$F$526)^2+(G5-Sheet5!$G$526)^2+(H5-Sheet5!$H$526)^2+(I5-Sheet5!$I$526)^2+(J5-Sheet5!$J$526)^2+(K5-Sheet5!$K$526)^2+(L5-Sheet5!$L$526)^2) -> 3.3111564 | P5: =IF(N5<=O5, 0, 1) -> 0 | Q5: =IF(P5=Sheet1!$M5, 1, 0) -> 1
A6: ACEH | B6: Aceh Timur | C6: 0.29213777 | D6: -0.13909108 | E6: -0.6438711 | F6: -0.32304177 | G6: -0.26619639 | H6: -0.56299346 | I6: -0.12600837 | J6: 0.78594866 | K6: -1.5624686 | L6: -0.28272112 | N6: =SQRT((C6-Sheet5!$C$525)^2+(D6-Sheet5!$D$525)^2+(E6-Sheet5!$E$525)^2+(F6-Sheet5!$F$525)^2+(G6-Sheet5!$G$525)^2+(H6-Sheet5!$H$525)^2+(I6-Sheet5!$I$525)^2+(J6-Sheet5!$J$525)^2+(K6-Sheet5!$K$525)^2+(L6-Sheet5!$L$525)^2) -> 2.2041268 | O6: =SQRT((C6-Sheet5!$C$526)^2+(D6-Sheet5!$D$526)^2+(E6-Sheet5!$E$526)^2+(F6-Sheet5!$F$526)^2+(G6-Sheet5!$G$526)^2+(H6-Sheet5!$H$526)^2+(I6-Sheet5!$I$526)^2+(J6-Sheet5!$J$526)^2+(K6-Sheet5!$K$526)^2+(L6-Sheet5!$L$526)^2) -> 3.4492426 | P6: =IF(N6<=O6, 0, 1) -> 0 | Q6: =IF(P6=Sheet1!$M6, 1, 0) -> 1
